File: gsoc_xylib/samples/vamas_iso14976/fomblin_y.vms
VAMAS Surface Chemical Analysis Standard Data Transfer Format 1988 May 4
SurfaceSpectra Ltd.
Scienta ESCA300
G Beamson
Fomblin Y
2
The XPS of Polymers Database
Copyright (c) 2000 SurfaceSpectra Ltd.
NORM
REGULAR
5
0
0
0
0
0
5
Survey
Sample Name: Fomblin Y
2000
3
1
1
0
0
0
3
Sample Name: Fomblin Y
The XPS of Polymers Database
Copyright (c) 2000 SurfaceSpectra Ltd.
XPS
Al Ka, Monochromated
1486.6
1400
6000
500
45
315
FAT
300
5
1e+37
0
6000
500
45
0
Survey

-1
Binding energy
eV
1152.1
-1
1
Counts
d
pulse counting
0.1
3
1e+37
90
0
0
0
1151
4
40597
4684
4756
4633
4652
4548
4648
4681
4752
4608
4650
4845
4792
4735
4759
4647
4773
4707
4838
4621
4639
4764
4953
4846
4660
4832
4988
4892
4814
4812
4690
4844
4830
4705
5027
4819
4778
4869
4788
4987
4798
4832
4826
4894
4854
4841
4876
5025
4986
4857
5043
5090
4950
4890
5048
4895
4904
4952
4996
4845
5078
5166
5015
5220
5242
5225
5154
5228
5006
5239
5047
5105
4937
5131
4957
5245
5125
5114
5197
5173
5162
5206
5279
5224
5261
5226
5242
5290
5438
5158
5266
5328
5341
5468
5225
5426
5333
5275
5252
5400
5439
5294
5264
5338
5357
5414
5405
5328
5504
5426
5297
5656
5415
5407
5601
5535
5555
5705
5369
5624
5504
5627
5648
5568
5622
5520
5453
5482
5504
5696
5675
5772
5461
5831
5879
5714
5718
5720
5366
5679
5755
5689
5684
5870
5809
5876
5630
5896
5828
5752
6043
5947
5935
5946
6076
5837
5735
6023
6076
5949
6030
5957
6107
5978
5964
5995
5904
6046
6023
6394
6236
6315
6349
6451
6352
6236
6163
6261
6257
6347
6132
6140
5919
5765
5977
5684
5726
5752
5710
5791
5759
5796
5876
5661
5826
5761
5803
5899
5751
5741
5791
5773
5753
6068
6114
6049
5814
6000
5867
5882
5966
5816
6002
6195
5877
6255
6037
5874
6057
6006
6093
6175
6000
6263
5988
6044
6156
5834
6036
6006
6116
6244
6295
6097
6250
6204
6357
6159
6265
6182
6380
6531
6395
6601
6322
6379
6446
6356
6373
6361
6425
6540
6383
6411
6289
6677
6231
6427
6659
6335
6448
6523
6568
6728
6781
6832
6674
6725
6999
6976
7198
7266
7206
7418
7293
7193
6836
6954
6752
6872
6832
6846
6958
6645
6838
7082
7180
7296
7300
7793
8174
8748
8663
8723
8368
7986
7859
7685
7621
7719
7519
7294
6926
6749
6635
6560
6314
6417
6120
6216
6227
6564
6899
6691
7229
8231
9800
11498
12630
13835
13453
12095
10643
9339
8678
8210
7791
7032
6204
5184
4579
4289
4153
3733
3934
3674
3432
3511
3449
3489
3457
3584
3507
3449
3472
3303
3349
3405
3470
3389
3365
3328
3334
3340
3478
3468
3436
3469
3400
3300
3400
3630
3497
3524
3256
3472
3416
3454
3543
3612
3577
3466
3371
3500
3328
3331
3529
3525
3617
3518
3432
3352
3482
3473
3607
3446
3532
3453
3383
3536
3537
3491
3516
3521
3592
3637
3425
3595
3565
3513
3554
3523
3536
3547
3444
3545
3403
3596
3693
3592
3607
3485
3678
3687
3625
3527
3718
3737
3719
3681
3276
3426
3509
3456
3475
3517
3264
3504
3552
3483
3688
3595
3771
3894
4032
4262
4154
3996
3866
3848
3695
3771
3807
3692
3701
3708
3525
3199
2842
2684
2519
2490
2370
2060
1709
1472
1320
1213
1158
1024
1117
1179
1409
2552
13820
40597
34324
6985
1564
1146
977
837
804
773
736
641
781
703
690
674
701
760
728
705
720
656
666
693
681
688
660
757
612
720
659
739
717
616
753
667
744
708
640
655
723
699
721
625
706
705
717
713
699
723
654
678
681
659
699
730
720
676
712
624
666
723
718
661
722
614
661
684
700
674
638
718
744
770
702
722
744
725
758
771
683
674
747
743
685
679
771
812
704
710
765
712
712
732
719
708
741
769
641
736
685
721
680
692
771
762
714
709
725
752
719
770
828
819
769
757
673
602
759
744
726
704
791
705
770
767
744
808
787
807
801
807
784
835
779
758
688
669
742
683
627
562
504
475
535
440
442
465
462
468
495
421
548
939
4016
5418
1288
490
455
511
416
408
436
470
426
393
418
384
456
412
463
442
438
411
417
444
492
402
380
429
408
405
445
420
488
430
431
405
475
449
422
413
435
423
419
462
428
458
449
443
453
458
456
461
461
462
397
476
407
392
413
485
489
484
417
444
429
456
415
493
429
478
383
475
433
445
459
462
433
435
425
448
416
464
473
444
450
469
430
421
429
466
466
421
423
426
451
486
399
471
456
419
452
469
440
441
424
453
508
445
436
401
442
466
439
420
455
442
475
468
440
455
446
500
472
502
453
398
455
440
464
509
499
492
419
423
433
511
476
463
452
431
552
508
441
441
492
456
509
494
468
473
529
464
440
444
471
525
484
529
452
442
444
474
538
474
522
484
465
448
453
416
463
516
498
489
473
433
472
460
497
471
520
476
500
490
526
505
516
498
544
487
504
470
500
486
547
502
492
480
545
537
497
490
540
489
543
529
474
512
489
513
541
522
584
527
524
563
578
550
575
545
552
544
548
530
561
524
492
455
385
458
368
443
376
370
314
320
274
260
205
204
199
201
254
544
2375
3934
1680
2038
567
237
196
180
162
160
216
174
168
174
153
173
167
144
172
183
176
166
189
141
157
168
171
169
201
188
155
180
170
163
187
165
166
157
176
181
147
190
193
165
210
192
174
178
164
151
166
155
180
192
176
179
172
164
164
165
178
179
161
170
184
203
179
175
151
171
182
168
180
184
158
165
187
166
174
176
170
160
184
164
197
180
184
193
182
180
143
193
179
164
164
162
155
168
173
196
174
211
203
177
171
199
187
193
176
169
182
178
217
176
199
192
162
175
188
153
173
187
176
181
196
189
136
185
192
157
178
197
208
244
191
178
166
195
223
200
207
183
135
183
205
190
207
214
195
190
216
195
161
169
157
192
183
192
203
182
224
190
188
198
175
202
196
218
176
215
212
198
166
166
178
172
185
182
203
158
203
188
191
172
210
201
179
188
186
176
197
198
196
185
224
171
201
178
194
168
214
187
176
196
180
172
195
178
236
189
195
203
212
238
213
183
257
187
172
184
209
209
197
234
199
252
214
196
204
236
188
210
179
222
251
226
202
230
215
186
191
197
186
194
154
188
139
164
144
125
123
133
146
175
189
222
281
505
638
748
823
684
489
247
228
186
150
99
95
49
35
44
88
95
115
178
156
159
228
268
146
75
239
318
312
176
64
62
15
6
4
4
C 1s
Sample Name: Fomblin Y
2000
3
1
1
0
0
0
3
Sample Name: Fomblin Y
The XPS of Polymers Database
Copyright (c) 2000 SurfaceSpectra Ltd.
XPS
Al Ka, Monochromated
1486.6
1400
6000
500
45
315
FAT
150
5
1e+37
0
6000
500
45
0
C
1s
-1
Binding energy
eV
299.1
-0.05
1
Counts
d
pulse counting
0.1
25
1e+37
90
0
0
0
240
280
8924
366
353
360
352
333
348
347
352
360
350
365
380
379
348
378
385
382
380
366
346
350
373
356
358
330
361
354
356
389
381
388
388
394
407
380
361
353
383
377
372
387
379
375
388
382
365
372
408
378
385
354
374
416
420
426
391
415
472
485
507
499
534
577
586
578
651
664
690
729
728
753
832
859
914
895
898
920
925
913
902
953
986
973
985
1062
1189
1223
1341
1459
1594
1779
2087
2423
2732
3129
3584
4110
4619
5098
5704
6280
6908
7372
7874
8234
8535
8816
8924
8924
8815
8712
8656
8372
8125
7848
7652
7373
7020
6648
6236
5846
5481
5038
4537
3996
3429
2990
2602
2233
2009
1798
1588
1504
1456
1443
1451
1470
1637
1770
1910
2119
2355
2633
2992
3258
3565
3734
4107
4411
4678
4831
5107
5150
5059
4947
4897
4658
4323
4178
3846
3451
3075
2662
2252
1925
1640
1385
1143
945
838
777
686
624
584
527
515
548
531
525
538
490
481
483
489
501
451
438
445
435
400
373
381
382
376
355
372
342
337
337
352
339
348
360
359
325
318
331
309
330
353
349
355
315
327
334
351
329
314
319
300
305
313
332
280
321
328
324
317
332
316
321
325
302
305
319
314
319
320
304
310
O 1s
Sample Name: Fomblin Y
2000
3
1
1
0
0
0
3
Sample Name: Fomblin Y
The XPS of Polymers Database
Copyright (c) 2000 SurfaceSpectra Ltd.
XPS
Al Ka, Monochromated
1486.6
1400
6000
500
45
315
FAT
150
5
1e+37
0
6000
500
45
0
O
1s
-1
Binding energy
eV
540.1
-0.05
1
Counts
d
pulse counting
0.1
25
1e+37
90
0
0
0
200
719
12843
782
804
796
849
860
833
858
840
820
793
799
838
858
844
820
810
857
894
893
820
834
829
799
858
851
897
876
867
893
885
901
853
840
895
936
903
885
910
928
923
911
928
935
923
940
990
1011
1019
1032
1000
1063
1138
1160
1213
1255
1329
1378
1477
1581
1668
1792
1953
2121
2338
2593
2888
3241
3589
3954
4345
4908
5413
6001
6633
7241
7767
8362
9140
9643
10018
10667
11546
12031
12433
12796
12774
12773
12843
12750
12602
12291
11799
11184
10584
9904
9251
8536
7849
7167
6355
5664
5091
4366
3859
3418
3018
2580
2260
2005
1825
1735
1500
1402
1309
1192
1194
1164
1118
1012
976
966
953
978
963
900
880
837
855
888
872
870
865
859
867
863
868
874
872
848
823
852
857
834
817
793
792
804
818
803
813
783
791
839
800
822
844
806
761
819
810
831
802
829
793
774
770
799
785
729
732
765
815
819
809
750
769
759
790
780
763
764
803
811
774
753
719
727
756
822
763
726
751
789
858
759
748
782
734
779
778
F 1s
Sample Name: Fomblin Y
2000
3
1
1
0
0
0
3
Sample Name: Fomblin Y
The XPS of Polymers Database
Copyright (c) 2000 SurfaceSpectra Ltd.
XPS
Al Ka, Monochromated
1486.6
1400
6000
500
45
315
FAT
150
5
1e+37
0
6000
500
45
0
F
1s
-1
Binding energy
eV
697.1
-0.05
1
Counts
d
pulse counting
0.1
25
1e+37
90
0
0
0
300
1362
102458
1861
1789
1850
1862
1824
1887
1871
1821
1831
1852
1807
1848
1929
1891
1815
1764
1791
1842
1783
1764
1768
1733
1721
1705
1745
1735
1714
1758
1826
1772
1770
1765
1753
1733
1780
1767
1756
1766
1761
1756
1731
1744
1774
1777
1758
1809
1767
1783
1816
1818
1848
1838
1865
1843
1861
1891
1896
1895
1851
1849
1883
1890
1937
1961
1879
1910
1962
1982
1983
1989
2017
2035
2025
2073
2104
2102
2175
2170
2167
2147
2189
2256
2237
2178
2185
2286
2328
2314
2342
2434
2334
2373
2419
2505
2496
2549
2593
2607
2647
2694
2716
2706
2840
2913
2947
3012
3134
3190
3308
3390
3437
3535
3653
3824
4029
4285
4545
4783
5049
5331
5808
6260
6664
7169
7887
8807
9590
10561
11677
12852
14342
15829
17569
19581
21656
24302
26824
29575
32576
35927
39311
43186
47037
51199
55229
59617
64196
68543
73158
77297
81105
85456
89154
92411
95368
97910
100056
101548
102117
102458
101953
100293
98855
96991
94416
91045
87441
83495
78764
73956
69351
64653
59854
54816
50200
45326
41059
36934
32873
29452
25984
23125
20345
17925
15769
13755
12283
10890
9634
8648
7677
6839
6202
5715
5205
4775
4421
4146
3903
3688
3461
3459
3202
3015
2977
2865
2739
2661
2591
2558
2457
2502
2445
2406
2366
2292
2291
2209
2183
2093
2083
2065
1995
1974
1951
1875
1859
1905
1920
1921
1870
1863
1821
1880
1888
1866
1861
1776
1771
1819
1747
1680
1688
1649
1638
1666
1694
1672
1662
1671
1609
1618
1570
1554
1586
1506
1548
1559
1539
1537
1571
1624
1582
1526
1494
1515
1518
1457
1481
1492
1479
1454
1475
1470
1485
1487
1486
1466
1430
1406
1434
1446
1417
1447
1461
1406
1473
1460
1464
1425
1404
1428
1407
1439
1397
1408
1370
1362
1394
1390
Valence
Sample Name: Fomblin Y
2000
3
1
1
0
0
0
3
Sample Name: Fomblin Y
The XPS of Polymers Database
Copyright (c) 2000 SurfaceSpectra Ltd.
XPS
Al Ka, Monochromated
1486.6
1400
6000
500
45
315
FAT
150
5
1e+37
0
6000
500
45
0
Valence

-1
Binding energy
eV
44.1
-0.05
1
Counts
d
pulse counting
1
10
1e+37
90
0
0
0
940
25
6226
1025
1047
1028
1026
1027
1048
1055
1028
1013
1014
970
1025
1027
1042
1002
1009
1017
979
996
981
1035
1026
1032
1015
1088
1070
1073
1075
1047
1045
1059
1093
1073
1073
1043
1035
1095
1105
1070
1072
1095
1163
1110
1118
1150
1162
1091
1130
1174
1182
1107
1167
1152
1182
1196
1211
1216
1195
1176
1219
1214
1239
1236
1260
1238
1250
1229
1256
1297
1314
1276
1302
1301
1289
1286
1302
1269
1306
1283
1332
1358
1374
1387
1417
1416
1362
1449
1444
1359
1437
1472
1474
1507
1537
1544
1579
1618
1615
1611
1635
1661
1663
1662
1707
1713
1734
1846
1872
1902
1984
1999
2026
1992
2044
2131
2235
2244
2249
2332
2379
2437
2569
2583
2673
2761
2817
2928
2947
2936
3056
3164
3285
3339
3382
3464
3524
3546
3636
3691
3745
3840
3922
3968
3974
4080
4195
4251
4182
4235
4338
4368
4392
4435
4483
4512
4609
4614
4627
4638
4673
4768
4776
4887
4959
5023
5018
5047
5083
5134
5206
5332
5356
5381
5414
5484
5650
5656
5682
5680
5797
5886
5862
5863
5916
6057
5938
6043
6053
5966
6119
6102
6135
6213
6226
6087
6160
6135
6066
6151
6153
6062
6057
6190
6071
5875
5906
5883
5783
5639
5417
5397
5269
5236
5259
5127
5023
5030
4843
4683
4586
4523
4411
4164
4121
4088
4000
3897
3714
3591
3571
3515
3360
3264
3224
3157
3026
2996
2946
2888
2756
2621
2523
2449
2397
2374
2292
2262
2189
2163
2109
2016
1928
1964
1917
1833
1835
1759
1773
1705
1699
1656
1671
1657
1634
1553
1583
1571
1521
1501
1510
1507
1552
1537
1503
1473
1502
1528
1495
1451
1464
1423
1399
1414
1430
1470
1450
1418
1397
1391
1366
1345
1393
1393
1377
1300
1304
1302
1283
1308
1333
1278
1282
1209
1210
1195
1205
1212
1153
1163
1140
1102
1043
1023
1016
925
939
933
915
892
886
842
860
798
844
751
736
749
758
752
738
716
654
652
599
607
617
605
597
600
581
554
567
576
551
511
521
540
514
483
495
460
451
462
455
431
414
409
419
443
430
416
437
376
379
390
386
370
351
363
374
379
364
354
352
375
374
372
356
316
290
332
345
328
312
307
319
330
339
319
327
320
325
340
342
309
312
330
303
296
285
290
312
289
304
330
305
287
286
308
331
319
318
315
332
344
317
313
337
356
360
359
350
365
394
429
424
446
495
476
485
508
551
575
621
617
616
589
631
679
681
683
679
671
724
731
716
713
698
741
751
787
730
712
725
727
735
720
741
740
725
750
736
737
723
734
725
726
717
732
691
657
733
739
734
692
722
672
662
678
679
645
628
629
658
656
672
706
723
811
877
919
951
1011
1170
1259
1298
1451
1554
1643
1686
1778
1809
1854
1839
1795
1740
1615
1488
1431
1245
1120
1080
992
921
853
797
761
748
769
832
795
824
860
877
890
937
1028
1013
970
1041
1079
1108
1132
1086
1063
1110
1127
1123
1125
1068
1062
979
959
945
958
870
884
890
895
936
1053
1100
1188
1298
1320
1421
1565
1660
1702
1804
1902
1998
1991
2049
2027
1978
2074
2056
2032
2054
2023
2037
2071
2008
2017
2005
1898
1863
1852
1804
1761
1743
1749
1647
1589
1578
1528
1459
1369
1319
1269
1233
1198
1151
1034
981
984
887
816
763
742
699
610
574
506
434
415
408
365
372
385
389
369
381
413
479
512
544
575
646
758
766
814
943
1007
1050
1181
1213
1274
1349
1437
1538
1623
1659
1746
1815
1948
1967
2096
2143
2184
2249
2268
2285
2271
2247
2309
2422
2254
2241
2335
2287
2265
2310
2315
2256
2207
2307
2345
2333
2328
2285
2332
2384
2428
2419
2414
2490
2487
2474
2551
2456
2433
2464
2513
2515
2489
2401
2357
2265
2171
2007
1937
2007
1871
1700
1620
1497
1425
1340
1302
1264
1156
1094
1061
1048
1023
945
902
905
857
825
799
704
689
642
612
564
549
534
496
460
415
410
380
353
354
338
347
348
350
354
352
348
337
329
379
390
406
395
385
411
396
402
397
406
400
359
364
381
379
343
317
286
254
226
185
217
190
160
151
139
109
84
90
68
65
57
57
54
64
49
40
41
54
48
42
41
49
49
52
44
49
46
41
43
44
46
43
44
40
45
50
57
57
45
46
47
39
52
50
46
38
42
47
45
40
40
50
31
33
42
41
46
49
48
38
45
33
38
39
39
47
35
31
38
39
39
43
32
42
49
46
41
34
42
47
37
42
42
41
37
35
32
35
38
38
36
43
39
44
40
41
40
38
33
30
34
34
42
39
50
39
35
45
43
43
43
35
47
43
32
37
38
44
37
35
25
26
35
36
36
35
42
40
36
38
27
31
31
37
55
53
46
35
36
32
35
41
44
38
39
35
41
32
38
33
34
35
31
27
29
31
40
33
36
33
38
37
37
35
35
37
41
43
40
34
31
39
39
42
39
38
38
44
41
37
34
39
41
45
56
42
36
38
34
31
34
31
34
end of experiment