File: gsoc_xylib/samples/vamas_iso14976/mjr9_116a.vms
VAMAS Surface Chemical Analysis Standard Data Transfer Format 1988 May 4
Not Specified
Kratos Axis
Not Specified
/C=/data/Axis/Victoria/mjr9_116a.dset
0
MAP
REGULAR
6
1
32768
32768
1
Etch Time
s
0
0
0
0
7
Wide/2
Not Specified
2005
9
14
10
41
24
0
4
   Lens Mode:Hybrid   Resolution:Pass energy 160   Iris(Aperture):slot(Slot)
   Anode:Mono(Al (Mono))(150 W)   Step(meV): 1000.0   Dwell(ms): 164        Sweeps: 3        Acquisition Time(s): 540
   Acquired On :05/09/14 10:41:24   C/N :On

XPS
16384
16384
0
Mono(Al (Mono))
1486.69
150
1E+37
1E+37
6000
6000
1E+37
1E+37
FAT
160
1E+37
-4.455
0
1E+37
1E+37
1E+37
1E+37
Wide
None
-1
Kinetic Energy
eV
386.69
1
2
Intensity
d
Transmission
d
pulse counting
0.163636
0
1E+37
0
47
27.0476
8085
8163
8164
8097
8081
7811
7941
7916
7864
8024
7982
8099
8044
7930
8034
8058
8081
8205
8143
8195
8144
8254
8426
8335
8382
8263
8354
8257
8231
8215
8311
8385
8296
8380
8381
8376
8378
8345
8224
8467
8455
8623
8399
8475
8466
8469
8668
8517
8656
8578
8679
8645
8583
8641
8674
8633
8530
8565
8739
8854
8811
8711
8671
8839
8706
8755
8615
8711
8723
8732
8722
8732
8762
8906
8861
8864
8842
9005
8998
8996
8986
8895
8938
9009
8988
8993
8985
9075
8893
8869
8757
8833
8771
8926
8886
8793
9024
9078
8890
9001
9279
9240
9134
9142
9155
9165
9122
8933
8837
8847
8681
8563
8488
8398
8373
8194
8183
8228
8241
8246
8373
8491
8857
9127
9165
9188
9220
9031
8974
8644
8475
8450
8112
7763
7582
7352
7210
7025
6921
6855
6871
6819
6946
6817
6791
6836
6808
6826
6815
6738
6903
6822
6933
6865
7014
6886
6948
6941
6987
6831
6920
6992
7085
7056
6992
7086
7060
6984
7068
7061
7028
6912
6897
7069
7078
7114
7173
7199
7062
7030
7067
7186
7062
7080
7149
7070
7155
7176
7109
7294
7117
7305
7128
7156
7194
7296
7204
7333
7167
7197
7357
7363
7253
7265
7285
7269
7339
7153
7276
7313
7308
7249
7355
7341
7355
7365
7317
7418
7441
7298
7260
7317
7397
7438
7317
7410
7463
7431
7542
7373
7480
7568
7589
7673
7583
7663
7604
7562
7437
7488
7546
7558
7564
7675
7803
7569
7431
7477
7536
7590
7592
7654
7641
7642
7555
7668
7695
7672
7867
7798
7757
7835
7786
7719
7673
7590
7647
7674
7651
7737
7945
7774
7870
7777
7768
7759
7765
7908
7799
7878
7830
7895
7900
7974
7958
7973
7857
7891
8000
7860
7998
8001
8014
7930
7940
8058
8107
8144
8095
7947
8003
8009
7880
8025
8010
8022
7959
8031
8039
8135
8119
8181
8123
8103
8200
8146
8136
8253
8070
8101
8255
8240
8157
8164
8049
8267
8295
8237
8203
8286
8262
8458
8278
8282
8323
8281
8296
8360
8344
8395
8338
8324
8412
8329
8286
8359
8391
8543
8497
8503
8456
8452
8508
8451
8403
8408
8464
8574
8547
8532
8497
8584
8579
8543
8684
8590
8639
8505
8506
8748
8692
8663
8786
8666
8706
8652
8833
8702
8708
8675
8769
8742
8753
8744
8617
8661
8840
8856
8779
8670
8694
8760
8842
8819
8732
8599
8729
8846
8865
8854
8823
8912
8755
8765
8706
8782
8769
8939
8851
8740
8792
8905
8942
8871
8959
8888
8868
8901
8879
8924
8918
8947
9041
9079
9070
9063
9181
9085
8998
9127
9090
9103
8951
9079
9162
9176
9276
9011
9224
9117
9232
9246
9178
9170
9296
9244
9137
9304
9274
9373
9403
9295
9356
9212
9244
9390
9428
9341
9404
9492
9409
9356
9384
9481
9340
9297
9320
9359
9422
9455
9436
9411
9462
9418
9399
9543
9594
9685
9389
9442
9415
9371
9535
9572
9459
9577
9516
9519
9461
9631
9776
9708
9555
9483
9580
9626
9537
9640
9498
9545
9575
9675
9753
9575
9698
9632
9707
9631
9615
9849
9657
9730
9501
9638
9636
9674
9764
9758
9678
9593
9695
9665
9779
9877
9716
9524
9599
9725
9739
9640
9744
9472
9360
9390
9304
9353
9351
9328
9483
9398
9625
9533
9685
9874
9951
9917
10219
10068
10110
10125
9900
9853
9441
9378
9200
9008
8726
8441
8077
7748
7403
7374
7158
7060
7102
7152
7097
7920
10675
16108
22068
21318
13575
7983
6463
6207
6132
6074
6041
6036
6006
5839
5956
5946
6048
6097
6034
5961
5980
6006
6040
6089
5992
5966
5879
6052
5989
6016
5969
5990
6035
6026
6063
6064
6036
5953
6178
6165
6069
6017
6098
6008
6058
6109
6054
6084
6114
6109
6188
6101
6194
6042
6203
6253
6111
6173
6152
6111
6137
6261
6223
6114
6235
6153
6265
6176
6224
6183
6093
6195
6220
6153
5997
6239
6243
6266
6365
6356
6302
6216
6109
6191
6172
6237
6373
6242
6128
6152
6212
6297
6326
6184
6242
6450
6201
6211
6195
6158
6163
6166
6231
6224
6271
6306
6425
6451
6405
6409
6340
6295
6440
6253
6337
6120
6021
5934
6015
5886
5955
5892
5756
5702
5634
5572
5440
5409
5298
5228
5379
5794
6543
8364
10947
10342
7201
5641
5233
5166
5101
5144
5116
5193
5074
5131
5098
5194
5165
5152
5164
5198
5141
5309
5204
5094
5167
5162
5246
5410
5359
5277
5336
5266
5289
5360
5404
5518
5358
5321
5313
5441
5441
5423
5434
5399
5541
5411
5461
5539
5563
5471
5471
5553
5749
5726
5711
5664
5605
5628
5701
5719
5613
5575
5686
5755
5698
5703
5722
5875
5795
5849
5991
5923
5855
5839
5842
5878
5808
5906
5933
5883
5844
6038
6076
6068
6045
6108
6302
6207
6293
6517
6414
6477
6571
6573
6513
6637
6550
6491
6321
5915
5658
5277
4851
4451
4171
3870
3436
2987
2705
2538
2511
2619
3259
5419
8783
13173
21311
30809
25841
10311
2700
1585
1299
1212
1180
1087
1010
988
977
1040
1123
1220
1092
1095
1053
1016
980
967
976
955
951
928
883
900
869
875
937
979
977
918
955
918
925
921
882
898
872
801
874
877
775
844
851
826
850
845
869
842
945
1081
1233
1184
1010
923
873
898
846
797
809
796
830
826
832
779
809
781
762
722
743
762
762
713
703
682
674
696
687
724
706
759
947
1040
1056
985
929
826
774
673
682
653
647
681
705
717
657
642
639
661
652
679
635
585
573
568
577
585
560
565
538
527
551
594
734
1054
1340
1127
782
635
574
607
549
527
520
544
529
527
534
586
659
691
690
620
550
512
503
496
510
533
563
480
517
510
523
525
517
500
513
529
525
539
509
471
519
528
494
516
498
537
558
519
536
538
551
521
496
514
502
524
540
518
556
490
501
492
537
546
512
525
525
633
755
732
578
553
490
513
531
507
501
490
515
515
499
501
502
500
445
507
512
511
513
494
476
473
502
517
485
471
500
468
510
461
496
505
497
456
469
479
452
453
479
479
489
520
507
493
472
484
505
502
497
465
493
533
538
485
482
497
503
442
423
467
479
457
425
398
395
401
419
380
373
400
436
489
528
658
662
691
644
571
469
425
387
433
510
476
434
435
411
423
328
281
295
293
250
224
185
186
155
115
47
27.0476
Wide/5
Not Specified
2005
9
14
11
47
20
0
4
   Lens Mode:Hybrid   Resolution:Pass energy 160   Iris(Aperture):slot(Slot)
   Anode:Mono(Al (Mono))(150 W)   Step(meV): 1000.0   Dwell(ms): 300        Sweeps: 5        Acquisition Time(s): 902
   Acquired On :05/09/14 11:47:20   C/N :On

XPS
16384
16384
0
Mono(Al (Mono))
1486.69
150
1E+37
1E+37
6000
6000
1E+37
1E+37
FAT
160
1E+37
-4.455
0
1E+37
1E+37
1E+37
1E+37
Wide
None
-1
Kinetic Energy
eV
886.69
1
2
Intensity
d
Transmission
d
pulse counting
0.3
5
0
1E+37
1E+37
1E+37
0
1202
148
91985
27.0476
36.9298
29857
35.9372
30022
35.9449
29792
35.9516
29964
35.9583
29975
35.965
29895
35.9717
29985
35.9784
30174
35.9851
30231
35.9918
30005
35.9985
29917
36.0052
29847
36.0119
29762
36.0186
29831
36.0253
29861
36.032
29843
36.0387
29845
36.0454
30108
36.0521
30129
36.0588
30310
36.0655
30093
36.0722
30094
36.0789
30108
36.0856
30360
36.0923
30435
36.099
30212
36.1057
30208
36.1124
30130
36.1191
30104
36.1258
30058
36.1325
29925
36.1392
29821
36.1459
29514
36.1526
29684
36.1593
29645
36.166
29303
36.1727
29013
36.1794
29051
36.1861
29096
36.1928
29398
36.1995
29355
36.2062
29600
36.2129
30118
36.2196
30665
36.2263
31023
36.233
31088
36.2397
31177
36.2464
31473
36.2531
31364
36.2598
30777
36.2665
30771
36.2732
30160
36.2799
29290
36.2866
28787
36.2933
28411
36.3
27710
36.3067
26833
36.3134
25807
36.3201
24792
36.3268
23610
36.3335
23102
36.3402
22602
36.3469
22356
36.3536
22326
36.3603
22055
36.367
21969
36.3737
22666
36.3804
26020
36.3871
35647
36.3938
53158
36.4005
68784
36.4072
63209
36.4139
39906
36.4206
24308
36.4273
20210
36.434
19404
36.4407
19122
36.4474
19025
36.4541
18846
36.4608
18671
36.4675
18693
36.4742
18555
36.4809
18490
36.4876
18611
36.4943
18669
36.501
18639
36.5077
18549
36.5144
18440
36.5211
18511
36.5278
18553
36.5345
18659
36.5412
18713
36.5479
18594
36.5546
18722
36.5613
18791
36.568
18536
36.5747
18801
36.5814
18816
36.5881
18907
36.5948
18898
36.6015
19054
36.6082
18808
36.6149
18936
36.6216
18784
36.6283
18710
36.635
18968
36.6417
19236
36.6484
19123
36.6551
19004
36.6618
18997
36.6685
18903
36.6752
18977
36.6819
19117
36.6886
18991
36.6953
19067
36.702
18921
36.7087
19261
36.7154
19303
36.7221
18961
36.7288
19161
36.7355
18909
36.7422
19022
36.7489
19083
36.7556
19191
36.7623
19277
36.769
19203
36.7757
19361
36.7824
19238
36.7891
19317
36.7958
19447
36.8025
19263
36.8092
19459
36.8159
19188
36.8226
19194
36.8293
19271
36.836
19508
36.8427
19471
36.8494
19449
36.8561
19283
36.8628
19307
36.8695
19387
36.8762
19401
36.8829
19379
36.8896
19577
36.8963
19451
36.903
19377
36.9097
19425
36.9164
19548
36.9231
19509
36.9298
19456
36.9117
19621
36.8827
19427
36.8537
19314
36.8248
19307
36.7958
19532
36.7668
19448
36.7378
19382
36.7088
19550
36.6798
19570
36.6508
19428
36.6218
19498
36.5929
19517
36.5639
19579
36.5349
19333
36.5059
19292
36.4769
19135
36.4479
19411
36.4189
19517
36.3899
19321
36.3609
19363
36.332
19308
36.303
19322
36.274
19309
36.245
19535
36.216
19671
36.187
19522
36.158
19532
36.129
19838
36.1001
19822
36.0711
19725
36.0421
19727
36.0131
19593
35.9841
19596
35.9551
19332
35.9261
19120
35.8971
18842
35.8681
18975
35.8392
18789
35.8102
18466
35.7812
18151
35.7522
17637
35.7232
17503
35.6942
17484
35.6652
17040
35.6362
16850
35.6073
16783
35.5783
16582
35.5493
16528
35.5203
17042
35.4913
18264
35.4623
21189
35.4333
27201
35.4043
34031
35.3754
30547
35.3464
21403
35.3174
17007
35.2884
16230
35.2594
16113
35.2304
15884
35.2014
15999
35.1724
15976
35.1434
15892
35.1145
15739
35.0855
15930
35.0565
15987
35.0275
16137
34.9985
16240
34.9695
16314
34.9405
16267
34.9115
15981
34.8826
16118
34.8536
16157
34.8246
16358
34.7956
16284
34.7666
16322
34.7376
16299
34.7086
16254
34.6796
16409
34.6506
16364
34.6217
16540
34.5927
16522
34.5637
16623
34.5347
16730
34.5057
16807
34.4767
16530
34.4477
16586
34.4187
16895
34.3898
16918
34.3608
17004
34.3318
16789
34.3028
17094
34.2738
16976
34.2448
16849
34.2158
17042
34.1868
17000
34.1578
17012
34.1289
17122
34.0999
17153
34.0709
17281
34.0419
17289
34.0129
17325
33.9839
17489
33.9549
17641
33.9259
17650
33.897
17766
33.868
17875
33.839
17626
33.81
17550
33.781
17531
33.752
17654
33.723
17565
33.694
17618
33.6651
17583
33.6361
17839
33.6071
17873
33.5781
17789
33.5491
17997
33.5201
18081
33.4911
18122
33.4621
18003
33.4331
18060
33.4042
18156
33.3752
18111
33.3462
18030
33.3172
18059
33.2882
18076
33.2592
18055
33.2302
18055
33.2012
18233
33.1723
18084
33.1433
18092
33.1143
18282
33.0853
18266
33.0563
18506
33.0273
18707
32.9983
18823
32.9693
19027
32.9403
19433
32.9114
19473
32.8824
19773
32.8534
20258
32.8244
20085
32.7954
20221
32.7664
19975
32.7374
20278
32.7084
20228
32.6795
20185
32.6505
19608
32.6215
19015
32.5925
18501
32.5635
17505
32.5345
16108
32.5055
14985
32.4765
13747
32.4475
12735
32.4186
11800
32.3896
10443
32.3606
9383
32.3316
8562
32.3026
7915
32.2736
7796
32.2446
8396
32.2156
11202
32.1867
18260
32.1577
28950
32.1287
44193
32.0997
70813
32.0707
91985
32.0417
69534
32.0127
27427
31.9837
8255
31.9547
4820
31.9258
4170
31.8968
3826
31.8678
3623
31.8388
3405
31.8098
3400
31.7808
3311
31.7518
3278
31.7228
3365
31.6939
3591
31.6649
3714
31.6359
3623
31.6069
3513
31.5779
3434
31.5489
3295
31.5199
3150
31.4909
3070
31.462
2988
31.433
3033
31.404
3016
31.375
2935
31.346
2981
31.317
2990
31.288
3067
31.259
3135
31.23
3008
31.2011
3079
31.1721
3058
31.1431
3141
31.1141
2933
31.1243
2995
31.1476
3022
31.1709
2895
31.1942
2872
31.2174
2920
31.2407
2909
31.264
2757
31.2873
2860
31.3106
2717
31.3339
2839
31.3571
2723
31.3804
2783
31.4037
2820
31.427
2761
31.4503
2713
31.4736
2691
31.4968
2893
31.5201
3224
31.5434
3644
31.5667
3915
31.59
3689
31.6133
3389
31.6365
3029
31.6598
2842
31.6831
2836
31.7064
2749
31.7297
2640
31.753
2589
31.7762
2621
31.7995
2643
31.8228
2667
31.8461
2665
31.8694
2586
31.8927
2610
31.9159
2629
31.9392
2544
31.9625
2506
31.9858
2505
32.0091
2438
32.0324
2457
32.0556
2358
32.0789
2355
32.1022
2298
32.1255
2260
32.1488
2256
32.1721
2227
32.1953
2260
32.2186
2406
32.2419
2505
32.2652
2875
32.2885
3247
32.3118
3384
32.335
3162
32.3583
2890
32.3816
2736
32.4049
2387
32.4282
2174
32.4515
2168
32.4747
2261
32.498
2316
32.5213
2319
32.5446
2315
32.5679
2234
32.5912
2271
32.6144
2159
32.6377
2163
32.661
2130
32.6843
2126
32.7076
2066
32.7309
1991
32.7541
1938
32.7774
1936
32.8007
1861
32.824
1827
32.8473
1729
32.8706
1819
32.8938
1811
32.9171
1765
32.9404
1797
32.9637
1853
32.987
1999
33.0103
2639
33.0336
3630
33.0568
4146
33.0801
3411
33.1034
2331
33.1267
1910
33.15
1967
33.1732
1932
33.1965
1788
33.2198
1727
33.2431
1591
33.2664
1596
33.2729
1683
33.2261
1753
33.1793
1818
33.1325
2083
33.0857
2321
33.0389
2459
32.9921
2229
32.9454
1913
32.8986
1789
32.8518
1613
32.805
1629
32.7582
1598
32.7114
1522
32.6646
1683
32.6179
1680
32.5711
1617
32.5243
1662
32.4775
1618
32.4307
1679
32.3839
1688
32.3371
1638
32.2904
1609
32.2436
1606
32.1968
1681
32.15
1707
32.1032
1687
32.0564
1682
32.0096
1698
31.9629
1616
31.9161
1626
31.8693
1691
31.8225
1698
31.7757
1684
31.7289
1722
31.6821
1664
31.6354
1651
31.5886
1766
31.5418
1666
31.495
1642
31.4482
1649
31.4014
1682
31.3546
1607
31.3079
1719
31.2611
1716
31.2143
1668
31.1675
1715
31.1207
1624
31.0739
1664
31.0272
1592
30.9804
1594
30.9336
1607
30.8868
1583
30.84
1674
30.7932
1736
30.7464
1935
30.6997
2256
30.6529
2442
30.6061
2256
30.5593
1819
30.5125
1640
30.4657
1645
30.4189
1604
30.3722
1670
30.3254
1648
30.2786
1664
30.2318
1711
30.185
1668
30.1382
1615
30.0914
1683
30.0447
1669
29.9979
1624
29.9511
1637
29.9043
1572
29.8575
1592
29.8107
1668
29.7639
1641
29.7172
1645
29.6704
1596
29.6236
1598
29.5768
1668
29.53
1663
29.4832
1715
29.4364
1677
29.3897
1654
29.3429
1725
29.2961
1618
29.2493
1565
29.2025
1584
29.1557
1577
29.1089
1572
29.0622
1565
29.0154
1576
28.9686
1592
28.9218
1449
28.875
1513
28.8282
1537
28.7815
1553
28.7347
1574
28.6879
1504
28.6411
1583
28.5943
1643
28.5475
1679
28.5007
1663
28.454
1673
28.4072
1582
28.3604
1573
28.3136
1588
28.2668
1683
28.22
1573
28.1732
1561
28.1265
1556
28.0797
1637
28.0329
1610
27.9861
1582
27.9393
1625
27.8925
1549
27.8457
1490
27.799
1455
27.7522
1493
27.7054
1364
27.6586
1306
27.6118
1339
27.565
1291
27.5182
1297
27.4715
1307
27.4247
1263
27.3779
1264
27.3311
1399
27.2843
1479
27.2375
1634
27.1907
1866
27.144
2230
27.0972
2327
27.0504
2267
27.0476
2007
27.0476
1700
27.0476
1437
27.0476
1335
27.0476
1367
27.0476
1539
27.0476
1673
27.0476
1520
27.0476
1521
27.0476
1348
27.0476
1308
27.0476
1274
27.0476
1086
27.0476
949
27.0476
932
27.0476
884
27.0476
808
27.0476
700
27.0476
634
27.0476
582
27.0476
452
27.0476
308
27.0476
148
27.0476
O 1s/6
Not Specified
2005
9
14
12
4
14
0
4
   Lens Mode:Hybrid   Resolution:Pass energy 10    Iris(Aperture):slot(Slot)
   Anode:Mono(Al (Mono))(150 W)   Step(meV): 100.0    Dwell(ms): 261        Sweeps: 10       Acquisition Time(s): 603
   Acquired On :05/09/14 12:04:14   C/N :On

XPS
16384
16384
0
Mono(Al (Mono))
1486.69
150
1E+37
1E+37
6000
6000
1E+37
1E+37
FAT
10
1E+37
-4.455
0
1E+37
1E+37
1E+37
1E+37
O
1s
-1
Kinetic Energy
eV
948.69
0.1
2
Intensity
d
Transmission
d
pulse counting
0.26087
10
0
1E+37
1E+37
1E+37
0
462
235
1525
0.279953
0.280338
304
0.279953
328
0.279955
324
0.279957
321
0.279958
333
0.27996
341
0.279962
338
0.279963
350
0.279965
322
0.279967
316
0.279968
331
0.27997
314
0.279972
331
0.279973
322
0.279975
289
0.279977
305
0.279978
306
0.27998
316
0.279982
307
0.279983
316
0.279985
310
0.279987
302
0.279988
312
0.27999
296
0.279992
311
0.279994
284
0.279995
345
0.279997
297
0.279999
298
0.28
276
0.280002
310
0.280004
281
0.280005
290
0.280007
299
0.280009
274
0.28001
287
0.280012
274
0.280014
271
0.280015
288
0.280017
300
0.280019
293
0.28002
256
0.280022
312
0.280024
303
0.280025
276
0.280027
299
0.280029
303
0.28003
333
0.280032
293
0.280034
326
0.280035
336
0.280037
338
0.280039
356
0.28004
344
0.280042
361
0.280044
406
0.280045
422
0.280047
457
0.280049
439
0.28005
472
0.280052
552
0.280054
545
0.280055
569
0.280057
608
0.280059
682
0.28006
753
0.280062
747
0.280064
781
0.280065
820
0.280067
896
0.280069
895
0.28007
994
0.280072
1018
0.280074
1111
0.280075
1146
0.280077
1229
0.280079
1230
0.28008
1293
0.280082
1373
0.280084
1360
0.280085
1429
0.280087
1424
0.280089
1424
0.28009
1458
0.280092
1525
0.280094
1485
0.280095
1445
0.280097
1443
0.280099
1353
0.2801
1192
0.280102
1052
0.280104
986
0.280106
899
0.280107
752
0.280109
635
0.280111
579
0.280112
478
0.280114
469
0.280116
375
0.280117
357
0.280119
359
0.280121
310
0.280122
335
0.280124
300
0.280126
271
0.280127
296
0.280129
307
0.280131
287
0.280132
253
0.280134
300
0.280136
330
0.280137
310
0.280139
277
0.280141
271
0.280142
269
0.280144
273
0.280146
298
0.280147
316
0.280149
300
0.280151
254
0.280152
274
0.280154
283
0.280156
260
0.280157
276
0.280159
277
0.280161
257
0.280162
279
0.280164
300
0.280166
294
0.280167
302
0.280169
293
0.280171
283
0.280172
247
0.280174
249
0.280176
263
0.280177
289
0.280179
272
0.280181
294
0.280182
244
0.280184
281
0.280186
297
0.280187
300
0.280189
278
0.280191
279
0.280192
269
0.280194
263
0.280196
296
0.280197
257
0.280199
282
0.280201
280
0.280202
290
0.280204
279
0.280206
268
0.280208
260
0.280209
302
0.280211
261
0.280213
304
0.280214
276
0.280216
271
0.280218
276
0.280219
276
0.280221
266
0.280223
273
0.280224
274
0.280226
264
0.280228
252
0.280229
278
0.280231
279
0.280233
287
0.280234
266
0.280236
284
0.280238
268
0.280239
295
0.280241
256
0.280243
268
0.280244
260
0.280246
271
0.280248
260
0.280249
288
0.280251
276
0.280253
268
0.280254
288
0.280256
275
0.280258
283
0.280259
306
0.280261
287
0.280263
272
0.280264
256
0.280266
250
0.280268
264
0.280269
272
0.280271
289
0.280273
249
0.280274
275
0.280276
278
0.280278
278
0.280279
299
0.280281
276
0.280283
279
0.280284
276
0.280286
290
0.280288
289
0.280289
288
0.280291
286
0.280293
289
0.280294
275
0.280296
271
0.280298
273
0.280299
256
0.280301
297
0.280303
282
0.280304
290
0.280306
289
0.280308
280
0.280309
271
0.280311
264
0.280313
242
0.280315
280
0.280316
266
0.280318
250
0.28032
275
0.280321
267
0.280323
299
0.280325
267
0.280326
255
0.280328
263
0.28033
264
0.280331
242
0.280333
275
0.280335
235
0.280336
296
0.280338
N 1s/7
Not Specified
2005
9
14
12
4
14
0
4
   Lens Mode:Hybrid   Resolution:Pass energy 10    Iris(Aperture):slot(Slot)
   Anode:Mono(Al (Mono))(150 W)   Step(meV): 100.0    Dwell(ms): 286        Sweeps: 10       Acquisition Time(s): 603
   Acquired On :05/09/14 12:04:14   C/N :On

XPS
16384
16384
0
Mono(Al (Mono))
1486.69
150
1E+37
1E+37
6000
6000
1E+37
1E+37
FAT
10
1E+37
-4.455
0
1E+37
1E+37
1E+37
1E+37
N
1s
-1
Kinetic Energy
eV
1076.69
0.1
2
Intensity
d
Transmission
d
pulse counting
0.285714
10
0
1E+37
1E+37
1E+37
0
422
221
878
0.284683
0.286339
297
0.284683
315
0.284691
273
0.284699
288
0.284707
304
0.284715
258
0.284723
253
0.284731
263
0.284738
283
0.284746
285
0.284754
300
0.284762
274
0.28477
294
0.284778
299
0.284786
287
0.284794
302
0.284802
269
0.284809
285
0.284817
291
0.284825
270
0.284833
272
0.284841
300
0.284849
285
0.284857
295
0.284865
305
0.284872
293
0.28488
270
0.284888
311
0.284896
262
0.284904
263
0.284912
257
0.28492
287
0.284928
272
0.284936
262
0.284943
281
0.284951
274
0.284959
278
0.284967
289
0.284975
258
0.284983
267
0.284991
281
0.284999
266
0.285006
252
0.285014
262
0.285022
268
0.28503
267
0.285038
271
0.285046
268
0.285054
279
0.285062
266
0.28507
251
0.285077
276
0.285085
289
0.285093
251
0.285101
252
0.285109
281
0.285117
277
0.285125
305
0.285133
266
0.285141
266
0.285148
265
0.285156
269
0.285164
255
0.285172
279
0.28518
275
0.285188
240
0.285196
237
0.285204
273
0.285211
263
0.285219
261
0.285227
246
0.285235
245
0.285243
260
0.285251
272
0.285259
249
0.285267
260
0.285275
261
0.285282
252
0.28529
251
0.285298
278
0.285306
275
0.285314
244
0.285322
253
0.28533
271
0.285338
252
0.285345
260
0.285353
249
0.285361
285
0.285369
268
0.285377
289
0.285385
292
0.285393
308
0.285401
295
0.285409
296
0.285416
325
0.285424
292
0.285432
340
0.28544
321
0.285448
327
0.285456
364
0.285464
384
0.285472
366
0.285479
399
0.285487
377
0.285495
381
0.285503
398
0.285511
362
0.285519
412
0.285527
406
0.285535
404
0.285543
434
0.28555
461
0.285558
509
0.285566
527
0.285574
574
0.285582
625
0.28559
645
0.285598
720
0.285606
747
0.285614
824
0.285621
878
0.285629
854
0.285637
876
0.285645
833
0.285653
797
0.285661
803
0.285669
638
0.285677
605
0.285684
539
0.285692
469
0.2857
460
0.285708
388
0.285716
387
0.285724
354
0.285732
328
0.28574
303
0.285748
275
0.285755
319
0.285763
276
0.285771
286
0.285779
268
0.285787
255
0.285795
268
0.285803
262
0.285811
303
0.285818
289
0.285826
244
0.285834
253
0.285842
263
0.28585
251
0.285858
266
0.285866
255
0.285874
271
0.285882
282
0.285889
293
0.285897
264
0.285905
244
0.285913
253
0.285921
282
0.285929
234
0.285937
268
0.285945
249
0.285952
272
0.28596
234
0.285968
270
0.285976
260
0.285984
251
0.285992
257
0.286
259
0.286008
281
0.286016
262
0.286023
229
0.286031
260
0.286039
260
0.286047
256
0.286055
233
0.286063
286
0.286071
267
0.286079
221
0.286086
274
0.286094
248
0.286102
277
0.28611
269
0.286118
255
0.286126
240
0.286134
259
0.286142
279
0.28615
267
0.286157
261
0.286165
244
0.286173
246
0.286181
249
0.286189
274
0.286197
251
0.286205
254
0.286213
251
0.286221
277
0.286228
281
0.286236
290
0.286244
266
0.286252
259
0.28626
252
0.286268
267
0.286276
245
0.286284
234
0.286291
245
0.286299
261
0.286307
277
0.286315
235
0.286323
271
0.286331
254
0.286339
C 1s/8
Not Specified
2005
9
14
12
4
14
0
4
   Lens Mode:Hybrid   Resolution:Pass energy 10    Iris(Aperture):slot(Slot)
   Anode:Mono(Al (Mono))(150 W)   Step(meV): 100.0    Dwell(ms): 261        Sweeps: 10       Acquisition Time(s): 603
   Acquired On :05/09/14 12:04:14   C/N :On

XPS
16384
16384
0
Mono(Al (Mono))
1486.69
150
1E+37
1E+37
6000
6000
1E+37
1E+37
FAT
10
1E+37
-4.455
0
1E+37
1E+37
1E+37
1E+37
C
1s
-1
Kinetic Energy
eV
1193.69
0.1
2
Intensity
d
Transmission
d
pulse counting
0.26087
10
0
1E+37
1E+37
1E+37
0
462
37
2692
0.293907
0.29572
143
0.293907
117
0.293915
129
0.293922
131
0.29393
128
0.293938
118
0.293946
101
0.293954
118
0.293962
105
0.29397
122
0.293978
93
0.293985
115
0.293993
102
0.294001
104
0.294009
92
0.294017
109
0.294025
100
0.294033
105
0.294041
99
0.294049
100
0.294056
96
0.294064
104
0.294072
95
0.29408
104
0.294088
107
0.294096
95
0.294104
95
0.294112
77
0.294119
89
0.294127
92
0.294135
89
0.294143
83
0.294151
83
0.294159
82
0.294167
70
0.294175
78
0.294183
91
0.29419
105
0.294198
97
0.294206
98
0.294214
81
0.294222
82
0.29423
91
0.294238
86
0.294246
103
0.294253
109
0.294261
99
0.294269
103
0.294277
106
0.294285
107
0.294293
116
0.294301
124
0.294309
104
0.294317
137
0.294324
148
0.294332
167
0.29434
160
0.294348
194
0.294356
219
0.294364
240
0.294372
249
0.29438
249
0.294388
285
0.294395
307
0.294403
307
0.294411
353
0.294419
428
0.294427
447
0.294435
464
0.294443
497
0.294451
548
0.294458
546
0.294466
523
0.294474
570
0.294482
529
0.29449
534
0.294498
488
0.294506
519
0.294514
542
0.294522
557
0.294529
600
0.294537
699
0.294545
772
0.294553
851
0.294561
952
0.294569
1055
0.294577
1064
0.294585
1196
0.294592
1230
0.2946
1262
0.294608
1281
0.294616
1261
0.294624
1291
0.294632
1329
0.29464
1405
0.294648
1461
0.294656
1637
0.294663
1796
0.294671
2032
0.294679
2272
0.294687
2429
0.294695
2596
0.294703
2692
0.294711
2612
0.294719
2535
0.294726
2191
0.294734
1938
0.294742
1575
0.29475
1207
0.294758
889
0.294766
646
0.294774
508
0.294782
321
0.29479
251
0.294797
196
0.294805
147
0.294813
112
0.294821
100
0.294829
79
0.294837
64
0.294845
84
0.294853
66
0.294861
66
0.294868
71
0.294876
65
0.294884
68
0.294892
61
0.2949
62
0.294908
67
0.294916
63
0.294924
56
0.294931
50
0.294939
71
0.294947
59
0.294955
57
0.294963
49
0.294971
49
0.294979
59
0.294987
46
0.294995
61
0.295002
42
0.29501
53
0.295018
50
0.295026
54
0.295034
49
0.295042
76
0.29505
65
0.295058
58
0.295065
56
0.295073
48
0.295081
55
0.295089
57
0.295097
62
0.295105
47
0.295113
53
0.295121
56
0.295129
55
0.295136
56
0.295144
58
0.295152
62
0.29516
54
0.295168
53
0.295176
64
0.295184
54
0.295192
42
0.295199
68
0.295207
46
0.295215
61
0.295223
59
0.295231
57
0.295239
58
0.295247
42
0.295255
42
0.295263
56
0.29527
52
0.295278
46
0.295286
46
0.295294
46
0.295302
44
0.29531
46
0.295318
48
0.295326
48
0.295334
49
0.295341
49
0.295349
48
0.295357
47
0.295365
55
0.295373
61
0.295381
55
0.295389
43
0.295397
41
0.295404
51
0.295412
48
0.29542
48
0.295428
59
0.295436
64
0.295444
60
0.295452
56
0.29546
64
0.295468
37
0.295475
51
0.295483
54
0.295491
71
0.295499
51
0.295507
44
0.295515
43
0.295523
42
0.295531
46
0.295538
68
0.295546
53
0.295554
50
0.295562
52
0.29557
51
0.295578
61
0.295586
62
0.295594
64
0.295602
41
0.295609
56
0.295617
54
0.295625
55
0.295633
64
0.295641
61
0.295649
55
0.295657
60
0.295665
65
0.295672
62
0.29568
61
0.295688
55
0.295696
59
0.295704
55
0.295712
50
0.29572
S 2p/9
Not Specified
2005
9
14
12
4
14
0
4
   Lens Mode:Hybrid   Resolution:Pass energy 10    Iris(Aperture):slot(Slot)
   Anode:Mono(Al (Mono))(150 W)   Step(meV): 100.0    Dwell(ms): 333        Sweeps: 20       Acquisition Time(s): 1207
   Acquired On :05/09/14 12:04:14   C/N :On

XPS
16384
16384
0
Mono(Al (Mono))
1486.69
150
1E+37
1E+37
6000
6000
1E+37
1E+37
FAT
10
1E+37
-4.455
0
1E+37
1E+37
1E+37
1E+37
S
2p
-1
Kinetic Energy
eV
1312.69
0.1
2
Intensity
d
Transmission
d
pulse counting
0.333333
20
0
1E+37
1E+37
1E+37
0
362
55
243
0.299821
0.300522
78
0.299821
74
0.299824
80
0.299828
90
0.299831
97
0.299834
94
0.299838
81
0.299841
79
0.299844
79
0.299848
91
0.299851
90
0.299855
90
0.299858
80
0.299861
96
0.299865
87
0.299868
81
0.299871
91
0.299875
93
0.299878
78
0.299882
74
0.299885
100
0.299888
87
0.299892
84
0.299895
70
0.299898
66
0.299902
84
0.299905
91
0.299908
71
0.299912
73
0.299915
60
0.299919
76
0.299922
67
0.299925
65
0.299929
82
0.299932
75
0.299935
90
0.299939
84
0.299942
84
0.299945
87
0.299949
91
0.299952
67
0.299956
83
0.299959
76
0.299962
73
0.299966
90
0.299969
84
0.299972
73
0.299976
97
0.299979
94
0.299983
81
0.299986
74
0.299989
89
0.299993
74
0.299996
73
0.299999
86
0.300003
89
0.300006
99
0.300009
112
0.300013
112
0.300016
119
0.30002
115
0.300023
128
0.300026
108
0.30003
148
0.300033
142
0.300036
129
0.30004
173
0.300043
164
0.300046
170
0.30005
205
0.300053
192
0.300057
194
0.30006
179
0.300063
195
0.300067
232
0.30007
206
0.300073
214
0.300077
189
0.30008
197
0.300083
216
0.300087
214
0.30009
218
0.300094
206
0.300097
202
0.3001
243
0.300104
210
0.300107
199
0.30011
165
0.300114
163
0.300117
125
0.300121
115
0.300124
116
0.300127
106
0.300131
87
0.300134
101
0.300137
77
0.300141
93
0.300144
79
0.300147
97
0.300151
96
0.300154
82
0.300158
84
0.300161
91
0.300164
92
0.300168
92
0.300171
93
0.300174
94
0.300178
82
0.300181
82
0.300184
95
0.300188
91
0.300191
80
0.300195
90
0.300198
76
0.300201
100
0.300205
100
0.300208
103
0.300211
89
0.300215
103
0.300218
99
0.300222
94
0.300225
86
0.300228
113
0.300232
91
0.300235
90
0.300238
97
0.300242
98
0.300245
105
0.300248
99
0.300252
114
0.300255
97
0.300259
97
0.300262
105
0.300265
85
0.300269
93
0.300272
90
0.300275
77
0.300279
81
0.300282
79
0.300285
76
0.300289
76
0.300292
89
0.300296
85
0.300299
65
0.300302
79
0.300306
88
0.300309
81
0.300312
85
0.300316
69
0.300319
93
0.300323
80
0.300326
72
0.300329
77
0.300333
76
0.300336
66
0.300339
93
0.300343
78
0.300346
76
0.300349
55
0.300353
85
0.300356
79
0.30036
87
0.300363
82
0.300366
63
0.30037
87
0.300373
76
0.300376
79
0.30038
86
0.300383
81
0.30039
72
0.300401
86
0.300412
69
0.300423
84
0.300434
65
0.300445
82
0.300456
77
0.300467
80
0.300478
74
0.300489
74
0.3005
77
0.300511
93
0.300522
Au 4f/10
Not Specified
2005
9
14
12
4
14
0
4
   Lens Mode:Hybrid   Resolution:Pass energy 10    Iris(Aperture):slot(Slot)
   Anode:Mono(Al (Mono))(150 W)   Step(meV): 100.0    Dwell(ms): 200        Sweeps: 20       Acquisition Time(s): 1204
   Acquired On :05/09/14 12:04:14   C/N :On

XPS
16384
16384
0
Mono(Al (Mono))
1486.69
150
1E+37
1E+37
6000
6000
1E+37
1E+37
FAT
10
1E+37
-4.455
0
1E+37
1E+37
1E+37
1E+37
Au
4f
-1
Kinetic Energy
eV
1386.69
0.1
2
Intensity
d
Transmission
d
pulse counting
0.2
20
0
1E+37
1E+37
1E+37
0
602
26
84
0.306691
0.309997
77
0.306691
84
0.306702
68
0.306713
78
0.306725
66
0.306736
62
0.306747
67
0.306758
69
0.306769
54
0.30678
71
0.306791
46
0.306802
49
0.306813
55
0.306824
53
0.306835
49
0.306846
50
0.306857
48
0.306868
43
0.306879
42
0.30689
48
0.306901
43
0.306912
50
0.306923
44
0.306934
43
0.306945
53
0.306956
47
0.306967
44
0.306978
48
0.306989
48
0.307
55
0.307011
46
0.307022
50
0.307033
39
0.307044
44
0.307055
59
0.307066
47
0.307077
37
0.307088
43
0.307099
44
0.30711
48
0.307121
50
0.307132
50
0.307143
49
0.307154
51
0.307165
37
0.307176
51
0.307187
43
0.307198
46
0.307209
41
0.30722
38
0.307231
38
0.307242
51
0.307253
45
0.307264
40
0.307275
50
0.307286
39
0.307297
48
0.307308
42
0.307319
39
0.30733
57
0.307341
52
0.307353
46
0.307364
39
0.307375
52
0.307386
43
0.307397
48
0.307408
45
0.307419
47
0.30743
42
0.307441
47
0.307452
42
0.307463
50
0.307474
50
0.307485
50
0.307496
60
0.307507
46
0.307518
40
0.307529
38
0.30754
50
0.307551
51
0.307562
50
0.307573
42
0.307584
52
0.307595
46
0.307606
44
0.307617
47
0.307628
32
0.307639
47
0.30765
49
0.307661
65
0.307672
59
0.307683
49
0.307694
50
0.307705
39
0.307716
38
0.307727
50
0.307738
53
0.307749
46
0.30776
52
0.307771
46
0.307782
48
0.307793
45
0.307804
60
0.307815
50
0.307826
37
0.307837
48
0.307848
39
0.307859
39
0.30787
53
0.307881
54
0.307892
52
0.307903
52
0.307914
43
0.307925
41
0.307936
44
0.307947
52
0.307958
44
0.307969
55
0.307981
35
0.307992
58
0.308003
44
0.308014
50
0.308025
39
0.308036
42
0.308047
49
0.308058
53
0.308069
44
0.30808
39
0.308091
48
0.308102
45
0.308113
43
0.308124
48
0.308135
49
0.308146
42
0.308157
44
0.308168
46
0.308179
53
0.30819
51
0.308201
35
0.308212
36
0.308223
48
0.308234
42
0.308245
43
0.308256
33
0.308267
41
0.308278
53
0.308289
46
0.3083
37
0.308311
34
0.308322
50
0.308333
46
0.308344
44
0.308355
48
0.308366
38
0.308377
55
0.308388
45
0.308399
50
0.30841
32
0.308421
53
0.308432
47
0.308443
46
0.308454
31
0.308465
42
0.308476
53
0.308487
47
0.308498
41
0.308509
45
0.30852
51
0.308531
44
0.308542
44
0.308553
45
0.308564
44
0.308575
40
0.308586
44
0.308597
43
0.308608
41
0.308619
46
0.308631
64
0.308642
50
0.308653
53
0.308664
48
0.308675
44
0.308686
45
0.308697
35
0.308708
34
0.308719
43
0.30873
49
0.308741
47
0.308752
47
0.308763
45
0.308774
54
0.308785
48
0.308796
38
0.308807
43
0.308818
36
0.308829
47
0.30884
43
0.308851
45
0.308862
45
0.308873
45
0.308884
47
0.308895
50
0.308906
57
0.308917
39
0.308928
41
0.308939
49
0.30895
46
0.308961
50
0.308972
43
0.308983
53
0.308994
55
0.309005
44
0.309016
46
0.309027
41
0.309038
40
0.309049
51
0.30906
51
0.309071
41
0.309082
50
0.309093
38
0.309104
51
0.309115
52
0.309126
37
0.309137
51
0.309148
40
0.309159
40
0.30917
59
0.309181
51
0.309192
61
0.309203
43
0.309214
45
0.309225
42
0.309236
53
0.309247
33
0.309259
51
0.30927
36
0.309281
34
0.309292
55
0.309303
48
0.309314
57
0.309325
45
0.309336
54
0.309347
59
0.309358
53
0.309369
42
0.30938
26
0.309391
44
0.309402
41
0.309413
50
0.309424
47
0.309435
54
0.309446
39
0.309457
41
0.309468
54
0.309479
48
0.30949
55
0.309501
42
0.309512
54
0.309523
55
0.309534
54
0.309545
52
0.309556
58
0.309567
50
0.309578
39
0.309589
52
0.3096
52
0.309611
49
0.309622
48
0.309633
49
0.309644
49
0.309655
52
0.309666
40
0.309677
43
0.309688
37
0.309699
49
0.30971
51
0.309721
52
0.309732
50
0.309743
55
0.309754
46
0.309765
53
0.309776
44
0.309787
32
0.309798
47
0.309809
50
0.30982
47
0.309831
51
0.309842
40
0.309853
39
0.309864
48
0.309875
51
0.309886
50
0.309898
33
0.309909
47
0.30992
53
0.309931
52
0.309942
52
0.309953
44
0.309964
42
0.309975
42
0.309986
49
0.309997
end of experiment