File: gsoc_xylib/samples/vamas_iso14976/mjr9_64c.vms
VAMAS Surface Chemical Analysis Standard Data Transfer Format 1988 May 4
Not Specified
Kratos Axis
Not Specified
/C=/data/Axis/Victoria/mjr9_64c.dset
0
MAP
REGULAR
6
1
32768
32768
1
Etch Time
s
0
0
0
0
9
Wide/2
Not Specified
2005
9
14
10
52
30
0
4
   Lens Mode:Hybrid   Resolution:Pass energy 160   Iris(Aperture):slot(Slot)
   Anode:Mono(Al (Mono))(150 W)   Step(meV): 1000.0   Dwell(ms): 164        Sweeps: 3        Acquisition Time(s): 540
   Acquired On :05/09/14 10:52:30   C/N :On

XPS
16384
16384
0
Mono(Al (Mono))
1486.69
150
1E+37
1E+37
6000
6000
1E+37
1E+37
FAT
160
1E+37
-4.455
0
1E+37
1E+37
1E+37
1E+37
Wide
None
-1
Kinetic Energy
eV
386.69
1
2
Intensity
d
Transmission
d
pulse counting
0.163636
0
1E+37
0
48
27.0476
4136
4161
4145
4210
4142
4079
4088
4129
4198
4335
4201
4215
4267
4368
4253
4245
4290
4244
4219
4080
4150
4220
4249
4259
4230
4239
4277
4278
4154
4146
4205
4189
4196
4225
4268
4198
4271
4317
4262
4220
4254
4270
4207
4220
4316
4227
4260
4278
4298
4381
4394
4369
4369
4419
4365
4354
4393
4378
4359
4254
4253
4389
4337
4288
4308
4407
4424
4325
4328
4309
4394
4365
4303
4320
4311
4380
4328
4328
4397
4277
4256
4532
4405
4329
4398
4330
4301
4264
4356
4363
4377
4387
4340
4296
4431
4423
4446
4438
4329
4372
4376
4490
4498
4371
4360
4396
4423
4370
4375
4414
4295
4258
4249
4223
4315
4176
4272
4261
4308
4337
4284
4241
4384
4432
4365
4438
4423
4485
4400
4204
4243
4179
4065
4073
4016
3888
3999
4134
3875
3954
3957
3884
3788
3882
3875
3885
3936
3914
3880
3899
3953
3889
3878
3890
3840
3901
3911
3845
3843
3832
3844
3895
3889
3920
3872
3789
3832
3816
3844
3823
3791
3789
3802
3731
3829
3842
3899
3912
3858
3911
3857
3751
3748
3748
3833
3779
3734
3722
3684
3758
3792
3694
3771
3753
3673
3742
3681
3710
3626
3754
3654
3640
3589
3713
3642
3645
3668
3575
3553
3588
3545
3495
3554
3631
3531
3465
3473
3449
3514
3433
3394
3365
3356
3300
3392
3398
3472
3457
3368
3427
3329
3226
3274
3273
3332
3322
3304
3284
3269
3277
3300
3365
3242
3290
3254
3281
3188
3240
3173
3222
3206
3203
3157
3027
3070
3191
3142
3109
3112
3053
3072
3060
3081
3030
3023
2955
3008
2934
2940
2863
2889
2918
2863
2824
2845
2764
2788
2713
2761
2875
2754
2716
2815
2778
2773
2798
2825
2782
2681
2725
2744
2780
2800
2772
2753
2759
2727
2706
2750
2671
2752
2714
2747
2748
2777
2776
2713
2697
2648
2658
2805
2758
2688
2701
2826
2772
2793
2792
2765
2726
2686
2663
2490
2612
2602
2649
2570
2582
2563
2565
2603
2556
2616
2528
2439
2492
2454
2537
2519
2496
2423
2463
2522
2506
2405
2472
2492
2407
2429
2421
2447
2475
2448
2379
2433
2422
2447
2413
2371
2430
2365
2384
2327
2339
2327
2280
2364
2282
2291
2249
2362
2221
2290
2319
2252
2264
2351
2280
2210
2110
2107
2084
2085
2013
1996
1960
2071
2159
2174
2262
2245
2120
1846
1715
1638
1465
1498
1433
1486
1430
1489
1461
1458
1524
1548
1485
1410
1440
1488
1455
1427
1384
1477
1491
1409
1393
1472
1433
1439
1540
1445
1487
1471
1430
1437
1430
1429
1441
1424
1469
1448
1496
1529
1510
1434
1465
1496
1510
1486
1468
1458
1490
1472
1450
1440
1445
1440
1463
1531
1531
1476
1422
1411
1431
1440
1476
1421
1474
1464
1481
1493
1472
1452
1443
1410
1381
1387
1456
1424
1453
1474
1440
1428
1425
1421
1373
1467
1480
1453
1450
1425
1427
1435
1460
1385
1470
1418
1398
1438
1452
1488
1454
1437
1392
1401
1438
1426
1459
1466
1465
1469
1434
1484
1471
1494
1521
1471
1463
1449
1441
1440
1416
1423
1471
1552
1420
1470
1406
1472
1453
1431
1420
1402
1475
1499
1503
1426
1408
1398
1368
1338
1371
1381
1364
1284
1266
1307
1354
1289
1293
1329
1350
1387
1411
1476
1345
1394
1360
1411
1402
1398
1340
1302
1323
1266
1232
1161
1169
1122
1085
1095
1052
1028
1024
1035
1154
1328
1844
2532
3012
2757
2026
1267
941
820
844
841
797
781
845
790
755
781
803
818
801
798
868
802
807
795
792
811
814
817
781
824
843
783
794
826
798
803
819
828
833
802
802
867
796
816
806
834
837
827
861
834
883
788
791
805
824
864
807
799
843
885
794
859
827
850
861
808
871
846
816
818
875
842
817
832
841
870
825
859
854
810
813
847
835
817
869
830
866
893
850
861
858
894
864
884
822
875
846
869
899
870
893
902
876
870
909
902
877
913
879
916
917
870
844
959
903
912
890
894
928
908
861
819
837
858
869
890
860
862
843
886
885
945
1015
1086
1117
1072
925
904
846
806
840
906
856
864
878
906
858
879
841
895
896
911
881
864
901
884
895
870
900
865
849
910
947
904
894
886
880
888
946
923
919
924
887
905
896
936
930
952
940
990
989
981
969
963
962
932
998
930
906
924
907
900
910
851
904
909
998
990
1010
1002
964
949
903
880
891
889
883
900
926
889
892
876
865
906
874
900
892
922
895
899
931
904
910
950
980
973
987
936
950
952
904
890
892
825
768
801
745
707
735
683
650
660
669
768
895
1192
1580
2121
2838
2899
1898
1059
680
551
477
482
478
500
479
454
496
510
504
513
514
469
516
524
487
501
497
497
491
507
497
469
507
525
537
518
521
487
496
493
511
468
487
468
512
504
507
462
467
516
486
483
503
461
510
476
502
525
508
536
541
503
551
507
502
492
494
465
513
515
500
489
502
502
477
474
521
491
489
506
506
522
501
517
487
509
509
517
534
544
566
525
542
528
476
499
516
499
514
525
496
505
488
484
532
541
492
477
508
496
491
478
482
514
534
522
460
523
473
501
547
530
499
551
521
543
506
536
530
483
504
497
520
496
505
506
522
538
496
482
505
506
525
516
519
544
543
510
524
497
496
496
495
505
497
456
482
492
507
496
489
491
482
509
543
467
497
519
499
531
508
479
521
535
508
520
501
514
487
482
458
485
488
433
440
484
485
478
469
438
464
482
468
444
464
494
468
455
430
482
554
535
586
582
572
568
530
420
364
355
315
332
328
310
290
264
288
287
273
282
271
258
263
266
249
236
216
237
235
222
233
249
282
312
337
297
265
212
183
134
131
109
132
105
107
126
135
144
124
97
100
96
94
95
76
67
77
83
85
81
95
88
90
104
140
111
98
115
112
94
88
79
81
82
68
66
70
74
60
72
66
80
93
84
103
81
90
69
59
48
27.0476
Wide/5
Not Specified
2005
9
14
13
26
55
0
4
   Lens Mode:Hybrid   Resolution:Pass energy 160   Iris(Aperture):slot(Slot)
   Anode:Mono(Al (Mono))(150 W)   Step(meV): 1000.0   Dwell(ms): 300        Sweeps: 5        Acquisition Time(s): 902
   Acquired On :05/09/14 13:26:55   C/N :On

XPS
16384
16384
0
Mono(Al (Mono))
1486.69
150
1E+37
1E+37
6000
6000
1E+37
1E+37
FAT
160
1E+37
-4.455
0
1E+37
1E+37
1E+37
1E+37
Wide
None
-1
Kinetic Energy
eV
886.69
1
2
Intensity
d
Transmission
d
pulse counting
0.3
5
0
1E+37
1E+37
1E+37
0
1202
123
9624
27.0476
36.9298
4814
35.9372
4836
35.9449
4797
35.9516
4745
35.9583
4812
35.965
4811
35.9717
4831
35.9784
4768
35.9851
4761
35.9918
4632
35.9985
4774
36.0052
4812
36.0119
4797
36.0186
5013
36.0253
4997
36.032
4962
36.0387
4862
36.0454
4810
36.0521
4760
36.0588
4723
36.0655
4826
36.0722
4757
36.0789
4888
36.0856
5030
36.0923
5075
36.099
4991
36.1057
4917
36.1124
4634
36.1191
4536
36.1258
4571
36.1325
4586
36.1392
4557
36.1459
4503
36.1526
4405
36.1593
4528
36.166
4496
36.1727
4504
36.1794
4553
36.1861
4499
36.1928
4483
36.1995
4623
36.2062
4681
36.2129
4600
36.2196
4683
36.2263
4729
36.233
4651
36.2397
4785
36.2464
4718
36.2531
4576
36.2598
4601
36.2665
4485
36.2732
4467
36.2799
4485
36.2866
4451
36.2933
4245
36.3
4194
36.3067
4025
36.3134
3796
36.3201
3712
36.3268
3662
36.3335
3560
36.3402
3476
36.3469
3517
36.3536
3474
36.3603
3619
36.367
3902
36.3737
4751
36.3804
6469
36.3871
8686
36.3938
9624
36.4005
8712
36.4072
6485
36.4139
4054
36.4206
3081
36.4273
2777
36.434
2770
36.4407
2764
36.4474
2747
36.4541
2764
36.4608
2759
36.4675
2688
36.4742
2729
36.4809
2654
36.4876
2673
36.4943
2600
36.501
2706
36.5077
2719
36.5144
2732
36.5211
2673
36.5278
2773
36.5345
2669
36.5412
2771
36.5479
2720
36.5546
2689
36.5613
2807
36.568
2734
36.5747
2746
36.5814
2687
36.5881
2730
36.5948
2743
36.6015
2688
36.6082
2759
36.6149
2794
36.6216
2882
36.6283
2849
36.635
2759
36.6417
2808
36.6484
2781
36.6551
2759
36.6618
2736
36.6685
2804
36.6752
2792
36.6819
2806
36.6886
2803
36.6953
2825
36.702
2817
36.7087
2879
36.7154
2814
36.7221
2760
36.7288
2836
36.7355
2856
36.7422
2871
36.7489
2878
36.7556
2818
36.7623
2749
36.769
2907
36.7757
2916
36.7824
2871
36.7891
2852
36.7958
2906
36.8025
2919
36.8092
2846
36.8159
2832
36.8226
2822
36.8293
2847
36.836
2833
36.8427
2872
36.8494
2873
36.8561
2967
36.8628
2893
36.8695
2903
36.8762
2845
36.8829
2790
36.8896
2791
36.8963
2899
36.903
2896
36.9097
2895
36.9164
2916
36.9231
2960
36.9298
2848
36.9117
2889
36.8827
2945
36.8537
3079
36.8248
2912
36.7958
2926
36.7668
2906
36.7378
2880
36.7088
2967
36.6798
3045
36.6508
3016
36.6218
3004
36.5929
2984
36.5639
3052
36.5349
3046
36.5059
3016
36.4769
2893
36.4479
2957
36.4189
3019
36.3899
2964
36.3609
3000
36.332
2977
36.303
3045
36.274
3038
36.245
3083
36.216
3027
36.187
3057
36.158
3021
36.129
3078
36.1001
2964
36.0711
2983
36.0421
2987
36.0131
3031
35.9841
3011
35.9551
3042
35.9261
3022
35.8971
3068
35.8681
2955
35.8392
3037
35.8102
3015
35.7812
2997
35.7522
2900
35.7232
2904
35.6942
2896
35.6652
2875
35.6362
2884
35.6073
2903
35.5783
2950
35.5493
3051
35.5203
3291
35.4913
3651
35.4623
3758
35.4333
3584
35.4043
3351
35.3754
3145
35.3464
3005
35.3174
3000
35.2884
2904
35.2594
2952
35.2304
2908
35.2014
2863
35.1724
2908
35.1434
2957
35.1145
2897
35.0855
2887
35.0565
2938
35.0275
2991
34.9985
2967
34.9695
2985
34.9405
2956
34.9115
2940
34.8826
2987
34.8536
3014
34.8246
2966
34.7956
3023
34.7666
3009
34.7376
3045
34.7086
2992
34.6796
3059
34.6506
2979
34.6217
3014
34.5927
2961
34.5637
2991
34.5347
3016
34.5057
2977
34.4767
3061
34.4477
3015
34.4187
2975
34.3898
3044
34.3608
3141
34.3318
3051
34.3028
3122
34.2738
3122
34.2448
3191
34.2158
3183
34.1868
3150
34.1578
3235
34.1289
3300
34.0999
3332
34.0709
3272
34.0419
3214
34.0129
3236
33.9839
3274
33.9549
3161
33.9259
3104
33.897
3060
33.868
3054
33.839
3023
33.81
2929
33.781
3063
33.752
3118
33.723
3060
33.694
3123
33.6651
3256
33.6361
3364
33.6071
3328
33.5781
3384
33.5491
3392
33.5201
3319
33.4911
3197
33.4621
3078
33.4331
3067
33.4042
2993
33.3752
3003
33.3462
2971
33.3172
2943
33.2882
2983
33.2592
3106
33.2302
3013
33.2012
2978
33.1723
3002
33.1433
3047
33.1143
3093
33.0853
3026
33.0563
3083
33.0273
3078
32.9983
3024
32.9693
3182
32.9403
3135
32.9114
3209
32.8824
3252
32.8534
3194
32.8244
3169
32.7954
3298
32.7664
3230
32.7374
3197
32.7084
3147
32.6795
3134
32.6505
3132
32.6215
2993
32.5925
2852
32.5635
2763
32.5345
2676
32.5055
2601
32.4765
2451
32.4475
2416
32.4186
2419
32.3896
2287
32.3606
2207
32.3316
2205
32.3026
2357
32.2736
2598
32.2446
3272
32.2156
4337
32.1867
5532
32.1577
7297
32.1287
9382
32.0997
8721
32.0707
5559
32.0417
3161
32.0127
2154
31.9837
1827
31.9547
1760
31.9258
1703
31.8968
1659
31.8678
1734
31.8388
1717
31.8098
1712
31.7808
1662
31.7518
1724
31.7228
1731
31.6939
1750
31.6649
1727
31.6359
1686
31.6069
1743
31.5779
1681
31.5489
1634
31.5199
1688
31.4909
1667
31.462
1639
31.433
1677
31.404
1669
31.375
1687
31.346
1639
31.317
1659
31.288
1677
31.259
1698
31.23
1657
31.2011
1626
31.1721
1712
31.1431
1694
31.1141
1731
31.1243
1704
31.1476
1680
31.1709
1767
31.1942
1642
31.2174
1602
31.2407
1632
31.264
1662
31.2873
1724
31.3106
1665
31.3339
1627
31.3571
1687
31.3804
1735
31.4037
1676
31.427
1666
31.4503
1662
31.4736
1776
31.4968
1878
31.5201
1794
31.5434
1800
31.5667
1818
31.59
1761
31.6133
1737
31.6365
1746
31.6598
1762
31.6831
1762
31.7064
1627
31.7297
1660
31.753
1680
31.7762
1675
31.7995
1677
31.8228
1693
31.8461
1734
31.8694
1639
31.8927
1671
31.9159
1701
31.9392
1640
31.9625
1662
31.9858
1630
32.0091
1691
32.0324
1700
32.0556
1721
32.0789
1695
32.1022
1743
32.1255
1651
32.1488
1683
32.1721
1624
32.1953
1730
32.2186
1756
32.2419
1782
32.2652
1823
32.2885
1861
32.3118
1867
32.335
1725
32.3583
1748
32.3816
1603
32.4049
1682
32.4282
1716
32.4515
1737
32.4747
1691
32.498
1761
32.5213
1722
32.5446
1742
32.5679
1837
32.5912
1713
32.6144
1652
32.6377
1687
32.661
1719
32.6843
1712
32.7076
1658
32.7309
1663
32.7541
1711
32.7774
1757
32.8007
1736
32.824
1709
32.8473
1669
32.8706
1682
32.8938
1711
32.9171
1742
32.9404
1734
32.9637
1797
32.987
1831
33.0103
1821
33.0336
1877
33.0568
1793
33.0801
1749
33.1034
1817
33.1267
1816
33.15
1785
33.1732
1753
33.1965
1722
33.2198
1752
33.2431
1764
33.2664
1657
33.2729
1708
33.2261
1754
33.1793
1741
33.1325
1677
33.0857
1772
33.0389
1708
32.9921
1753
32.9454
1742
32.8986
1672
32.8518
1719
32.805
1775
32.7582
1731
32.7114
1719
32.6646
1736
32.6179
1757
32.5711
1708
32.5243
1815
32.4775
1812
32.4307
1793
32.3839
1748
32.3371
1767
32.2904
1712
32.2436
1735
32.1968
1684
32.15
1701
32.1032
1682
32.0564
1703
32.0096
1737
31.9629
1713
31.9161
1756
31.8693
1702
31.8225
1737
31.7757
1699
31.7289
1746
31.6821
1658
31.6354
1704
31.5886
1782
31.5418
1720
31.495
1743
31.4482
1759
31.4014
1746
31.3546
1774
31.3079
1721
31.2611
1751
31.2143
1758
31.1675
1714
31.1207
1706
31.0739
1689
31.0272
1743
30.9804
1694
30.9336
1667
30.8868
1700
30.84
1669
30.7932
1668
30.7464
1652
30.6997
1674
30.6529
1616
30.6061
1637
30.5593
1567
30.5125
1488
30.4657
1571
30.4189
1522
30.3722
1558
30.3254
1564
30.2786
1608
30.2318
1602
30.185
1695
30.1382
1912
30.0914
2024
30.0447
2001
29.9979
2028
29.9511
2058
29.9043
1898
29.8575
1738
29.8107
1480
29.7639
1288
29.7172
1182
29.6704
1141
29.6236
1040
29.5768
1029
29.53
1013
29.4832
1063
29.4364
1029
29.3897
1001
29.3429
980
29.2961
900
29.2493
879
29.2025
913
29.1557
928
29.1089
915
29.0622
928
29.0154
843
28.9686
894
28.9218
814
28.875
781
28.8282
871
28.7815
804
28.7347
841
28.6879
926
28.6411
981
28.5943
1157
28.5475
1118
28.5007
1065
28.454
894
28.4072
722
28.3604
553
28.3136
468
28.2668
444
28.22
420
28.1732
391
28.1265
406
28.0797
401
28.0329
416
27.9861
489
27.9393
417
27.8925
395
27.8457
341
27.799
297
27.7522
290
27.7054
310
27.6586
284
27.6118
269
27.565
315
27.5182
277
27.4715
281
27.4247
322
27.3779
298
27.3311
341
27.2843
375
27.2375
395
27.1907
425
27.144
386
27.0972
429
27.0504
384
27.0476
379
27.0476
358
27.0476
330
27.0476
272
27.0476
255
27.0476
263
27.0476
271
27.0476
247
27.0476
240
27.0476
242
27.0476
202
27.0476
197
27.0476
211
27.0476
222
27.0476
264
27.0476
268
27.0476
305
27.0476
334
27.0476
337
27.0476
308
27.0476
241
27.0476
176
27.0476
123
27.0476
O 1s/6
Not Specified
2005
9
14
13
43
50
0
4
   Lens Mode:Hybrid   Resolution:Pass energy 10    Iris(Aperture):slot(Slot)
   Anode:Mono(Al (Mono))(150 W)   Step(meV): 100.0    Dwell(ms): 261        Sweeps: 10       Acquisition Time(s): 603
   Acquired On :05/09/14 13:43:50   C/N :On

XPS
16384
16384
0
Mono(Al (Mono))
1486.69
150
1E+37
1E+37
6000
6000
1E+37
1E+37
FAT
10
1E+37
-4.455
0
1E+37
1E+37
1E+37
1E+37
O
1s
-1
Kinetic Energy
eV
948.69
0.1
2
Intensity
d
Transmission
d
pulse counting
0.26087
10
0
1E+37
1E+37
1E+37
0
462
11
83
0.279953
0.280338
31
0.279953
24
0.279955
29
0.279957
22
0.279958
32
0.27996
20
0.279962
38
0.279963
40
0.279965
39
0.279967
16
0.279968
28
0.27997
37
0.279972
35
0.279973
27
0.279975
25
0.279977
37
0.279978
32
0.27998
25
0.279982
21
0.279983
26
0.279985
29
0.279987
21
0.279988
22
0.27999
28
0.279992
32
0.279994
30
0.279995
19
0.279997
29
0.279999
28
0.28
28
0.280002
16
0.280004
29
0.280005
17
0.280007
29
0.280009
36
0.28001
28
0.280012
31
0.280014
25
0.280015
25
0.280017
31
0.280019
30
0.28002
24
0.280022
37
0.280024
31
0.280025
31
0.280027
41
0.280029
32
0.28003
36
0.280032
34
0.280034
27
0.280035
38
0.280037
46
0.280039
32
0.28004
35
0.280042
47
0.280044
54
0.280045
60
0.280047
42
0.280049
51
0.28005
60
0.280052
67
0.280054
55
0.280055
55
0.280057
83
0.280059
74
0.28006
69
0.280062
60
0.280064
63
0.280065
67
0.280067
60
0.280069
69
0.28007
70
0.280072
47
0.280074
60
0.280075
63
0.280077
47
0.280079
67
0.28008
67
0.280082
58
0.280084
58
0.280085
79
0.280087
74
0.280089
77
0.28009
62
0.280092
57
0.280094
54
0.280095
55
0.280097
52
0.280099
39
0.2801
49
0.280102
30
0.280104
44
0.280106
31
0.280107
46
0.280109
46
0.280111
39
0.280112
23
0.280114
38
0.280116
25
0.280117
35
0.280119
22
0.280121
23
0.280122
27
0.280124
23
0.280126
24
0.280127
30
0.280129
28
0.280131
18
0.280132
20
0.280134
31
0.280136
21
0.280137
29
0.280139
33
0.280141
20
0.280142
24
0.280144
19
0.280146
26
0.280147
36
0.280149
31
0.280151
18
0.280152
11
0.280154
19
0.280156
16
0.280157
22
0.280159
29
0.280161
23
0.280162
31
0.280164
26
0.280166
24
0.280167
39
0.280169
25
0.280171
27
0.280172
21
0.280174
16
0.280176
25
0.280177
23
0.280179
18
0.280181
22
0.280182
32
0.280184
21
0.280186
26
0.280187
26
0.280189
26
0.280191
27
0.280192
33
0.280194
24
0.280196
28
0.280197
29
0.280199
24
0.280201
15
0.280202
32
0.280204
25
0.280206
17
0.280208
31
0.280209
32
0.280211
24
0.280213
21
0.280214
23
0.280216
30
0.280218
20
0.280219
23
0.280221
20
0.280223
32
0.280224
30
0.280226
24
0.280228
20
0.280229
26
0.280231
15
0.280233
28
0.280234
19
0.280236
22
0.280238
27
0.280239
18
0.280241
35
0.280243
27
0.280244
27
0.280246
19
0.280248
31
0.280249
25
0.280251
38
0.280253
22
0.280254
29
0.280256
35
0.280258
16
0.280259
17
0.280261
25
0.280263
25
0.280264
28
0.280266
24
0.280268
33
0.280269
21
0.280271
29
0.280273
30
0.280274
34
0.280276
25
0.280278
24
0.280279
18
0.280281
35
0.280283
36
0.280284
22
0.280286
23
0.280288
23
0.280289
26
0.280291
16
0.280293
25
0.280294
25
0.280296
32
0.280298
21
0.280299
23
0.280301
21
0.280303
22
0.280304
19
0.280306
27
0.280308
24
0.280309
23
0.280311
20
0.280313
27
0.280315
27
0.280316
37
0.280318
26
0.28032
21
0.280321
18
0.280323
23
0.280325
23
0.280326
23
0.280328
31
0.28033
26
0.280331
25
0.280333
30
0.280335
28
0.280336
32
0.280338
N 1s/7
Not Specified
2005
9
14
13
43
50
0
4
   Lens Mode:Hybrid   Resolution:Pass energy 10    Iris(Aperture):slot(Slot)
   Anode:Mono(Al (Mono))(150 W)   Step(meV): 100.0    Dwell(ms): 286        Sweeps: 10       Acquisition Time(s): 603
   Acquired On :05/09/14 13:43:50   C/N :On

XPS
16384
16384
0
Mono(Al (Mono))
1486.69
150
1E+37
1E+37
6000
6000
1E+37
1E+37
FAT
10
1E+37
-4.455
0
1E+37
1E+37
1E+37
1E+37
N
1s
-1
Kinetic Energy
eV
1076.69
0.1
2
Intensity
d
Transmission
d
pulse counting
0.285714
10
0
1E+37
1E+37
1E+37
0
422
15
43
0.284683
0.286339
25
0.284683
28
0.284691
23
0.284699
24
0.284707
18
0.284715
33
0.284723
21
0.284731
31
0.284738
22
0.284746
28
0.284754
26
0.284762
25
0.28477
23
0.284778
20
0.284786
31
0.284794
26
0.284802
24
0.284809
33
0.284817
32
0.284825
30
0.284833
21
0.284841
32
0.284849
29
0.284857
16
0.284865
22
0.284872
24
0.28488
37
0.284888
22
0.284896
33
0.284904
25
0.284912
31
0.28492
24
0.284928
27
0.284936
27
0.284943
32
0.284951
25
0.284959
28
0.284967
19
0.284975
30
0.284983
25
0.284991
21
0.284999
33
0.285006
30
0.285014
37
0.285022
21
0.28503
22
0.285038
30
0.285046
18
0.285054
32
0.285062
30
0.28507
18
0.285077
29
0.285085
25
0.285093
36
0.285101
32
0.285109
27
0.285117
28
0.285125
26
0.285133
19
0.285141
35
0.285148
27
0.285156
37
0.285164
23
0.285172
37
0.28518
32
0.285188
33
0.285196
37
0.285204
21
0.285211
17
0.285219
27
0.285227
33
0.285235
21
0.285243
30
0.285251
17
0.285259
29
0.285267
34
0.285275
29
0.285282
27
0.28529
19
0.285298
17
0.285306
33
0.285314
33
0.285322
27
0.28533
22
0.285338
15
0.285345
27
0.285353
24
0.285361
30
0.285369
33
0.285377
25
0.285385
29
0.285393
31
0.285401
25
0.285409
22
0.285416
24
0.285424
29
0.285432
41
0.28544
29
0.285448
32
0.285456
31
0.285464
32
0.285472
36
0.285479
27
0.285487
30
0.285495
32
0.285503
27
0.285511
19
0.285519
29
0.285527
31
0.285535
43
0.285543
31
0.28555
36
0.285558
28
0.285566
30
0.285574
28
0.285582
30
0.28559
37
0.285598
33
0.285606
27
0.285614
26
0.285621
31
0.285629
23
0.285637
36
0.285645
30
0.285653
37
0.285661
23
0.285669
23
0.285677
24
0.285684
28
0.285692
38
0.2857
29
0.285708
31
0.285716
21
0.285724
34
0.285732
29
0.28574
24
0.285748
31
0.285755
31
0.285763
27
0.285771
30
0.285779
34
0.285787
23
0.285795
28
0.285803
19
0.285811
24
0.285818
32
0.285826
26
0.285834
27
0.285842
32
0.28585
25
0.285858
27
0.285866
33
0.285874
37
0.285882
20
0.285889
28
0.285897
29
0.285905
19
0.285913
27
0.285921
25
0.285929
29
0.285937
30
0.285945
31
0.285952
29
0.28596
28
0.285968
25
0.285976
34
0.285984
30
0.285992
20
0.286
29
0.286008
20
0.286016
32
0.286023
30
0.286031
33
0.286039
26
0.286047
36
0.286055
26
0.286063
22
0.286071
24
0.286079
25
0.286086
33
0.286094
22
0.286102
24
0.28611
29
0.286118
25
0.286126
32
0.286134
23
0.286142
26
0.28615
25
0.286157
28
0.286165
30
0.286173
33
0.286181
27
0.286189
16
0.286197
26
0.286205
26
0.286213
23
0.286221
33
0.286228
27
0.286236
25
0.286244
21
0.286252
24
0.28626
28
0.286268
23
0.286276
26
0.286284
23
0.286291
22
0.286299
34
0.286307
35
0.286315
35
0.286323
26
0.286331
25
0.286339
C 1s/8
Not Specified
2005
9
14
13
43
50
0
4
   Lens Mode:Hybrid   Resolution:Pass energy 10    Iris(Aperture):slot(Slot)
   Anode:Mono(Al (Mono))(150 W)   Step(meV): 100.0    Dwell(ms): 261        Sweeps: 10       Acquisition Time(s): 603
   Acquired On :05/09/14 13:43:50   C/N :On

XPS
16384
16384
0
Mono(Al (Mono))
1486.69
150
1E+37
1E+37
6000
6000
1E+37
1E+37
FAT
10
1E+37
-4.455
0
1E+37
1E+37
1E+37
1E+37
C
1s
-1
Kinetic Energy
eV
1193.69
0.1
2
Intensity
d
Transmission
d
pulse counting
0.26087
10
0
1E+37
1E+37
1E+37
0
462
10
101
0.293907
0.29572
12
0.293907
14
0.293915
16
0.293922
13
0.29393
13
0.293938
16
0.293946
32
0.293954
13
0.293962
27
0.29397
25
0.293978
21
0.293985
21
0.293993
21
0.294001
14
0.294009
17
0.294017
14
0.294025
28
0.294033
23
0.294041
15
0.294049
20
0.294056
20
0.294064
17
0.294072
23
0.29408
19
0.294088
18
0.294096
16
0.294104
13
0.294112
18
0.294119
12
0.294127
18
0.294135
17
0.294143
21
0.294151
23
0.294159
15
0.294167
20
0.294175
24
0.294183
22
0.29419
24
0.294198
18
0.294206
24
0.294214
27
0.294222
19
0.29423
36
0.294238
33
0.294246
27
0.294253
24
0.294261
28
0.294269
20
0.294277
33
0.294285
41
0.294293
27
0.294301
28
0.294309
25
0.294317
22
0.294324
34
0.294332
19
0.29434
27
0.294348
25
0.294356
23
0.294364
24
0.294372
32
0.29438
32
0.294388
27
0.294395
26
0.294403
33
0.294411
20
0.294419
33
0.294427
28
0.294435
42
0.294443
35
0.294451
35
0.294458
46
0.294466
46
0.294474
38
0.294482
33
0.29449
37
0.294498
52
0.294506
43
0.294514
55
0.294522
58
0.294529
75
0.294537
74
0.294545
83
0.294553
78
0.294561
101
0.294569
72
0.294577
86
0.294585
73
0.294592
82
0.2946
53
0.294608
75
0.294616
63
0.294624
50
0.294632
45
0.29464
37
0.294648
41
0.294656
42
0.294663
39
0.294671
40
0.294679
44
0.294687
27
0.294695
43
0.294703
34
0.294711
36
0.294719
38
0.294726
40
0.294734
31
0.294742
33
0.29475
35
0.294758
25
0.294766
28
0.294774
28
0.294782
27
0.29479
21
0.294797
20
0.294805
19
0.294813
24
0.294821
16
0.294829
21
0.294837
18
0.294845
18
0.294853
17
0.294861
23
0.294868
23
0.294876
16
0.294884
22
0.294892
25
0.2949
19
0.294908
20
0.294916
22
0.294924
15
0.294931
11
0.294939
14
0.294947
17
0.294955
16
0.294963
16
0.294971
17
0.294979
28
0.294987
14
0.294995
14
0.295002
17
0.29501
18
0.295018
13
0.295026
22
0.295034
22
0.295042
19
0.29505
20
0.295058
15
0.295065
10
0.295073
18
0.295081
14
0.295089
15
0.295097
13
0.295105
18
0.295113
29
0.295121
15
0.295129
21
0.295136
19
0.295144
19
0.295152
18
0.29516
26
0.295168
20
0.295176
17
0.295184
17
0.295192
16
0.295199
26
0.295207
20
0.295215
21
0.295223
20
0.295231
18
0.295239
16
0.295247
21
0.295255
15
0.295263
21
0.29527
22
0.295278
21
0.295286
12
0.295294
12
0.295302
23
0.29531
18
0.295318
20
0.295326
21
0.295334
24
0.295341
17
0.295349
25
0.295357
23
0.295365
22
0.295373
12
0.295381
27
0.295389
13
0.295397
19
0.295404
21
0.295412
21
0.29542
19
0.295428
23
0.295436
18
0.295444
19
0.295452
17
0.29546
21
0.295468
25
0.295475
21
0.295483
17
0.295491
22
0.295499
20
0.295507
27
0.295515
21
0.295523
17
0.295531
16
0.295538
20
0.295546
24
0.295554
14
0.295562
11
0.29557
25
0.295578
21
0.295586
28
0.295594
21
0.295602
24
0.295609
14
0.295617
16
0.295625
15
0.295633
19
0.295641
14
0.295649
26
0.295657
24
0.295665
19
0.295672
15
0.29568
16
0.295688
20
0.295696
18
0.295704
15
0.295712
16
0.29572
S 2p/9
Not Specified
2005
9
14
13
43
50
0
4
   Lens Mode:Hybrid   Resolution:Pass energy 10    Iris(Aperture):slot(Slot)
   Anode:Mono(Al (Mono))(150 W)   Step(meV): 100.0    Dwell(ms): 333        Sweeps: 16       Acquisition Time(s): 965
   Acquired On :05/09/14 13:43:50   C/N :On

XPS
16384
16384
0
Mono(Al (Mono))
1486.69
150
1E+37
1E+37
6000
6000
1E+37
1E+37
FAT
10
1E+37
-4.455
0
1E+37
1E+37
1E+37
1E+37
S
2p
-1
Kinetic Energy
eV
1312.69
0.1
2
Intensity
d
Transmission
d
pulse counting
0.333333
16
0
1E+37
1E+37
1E+37
0
362
25
59
0.299821
0.300522
33
0.299821
42
0.299824
31
0.299828
44
0.299831
39
0.299834
37
0.299838
35
0.299841
43
0.299844
34
0.299848
52
0.299851
41
0.299855
41
0.299858
45
0.299861
31
0.299865
36
0.299868
44
0.299871
49
0.299875
37
0.299878
43
0.299882
31
0.299885
47
0.299888
53
0.299892
35
0.299895
35
0.299898
44
0.299902
37
0.299905
41
0.299908
42
0.299912
47
0.299915
31
0.299919
46
0.299922
54
0.299925
45
0.299929
36
0.299932
25
0.299935
42
0.299939
41
0.299942
37
0.299945
40
0.299949
36
0.299952
47
0.299956
37
0.299959
45
0.299962
48
0.299966
53
0.299969
38
0.299972
46
0.299976
26
0.299979
28
0.299983
33
0.299986
35
0.299989
36
0.299993
48
0.299996
36
0.299999
47
0.300003
46
0.300006
31
0.300009
41
0.300013
35
0.300016
41
0.30002
38
0.300023
37
0.300026
46
0.30003
25
0.300033
59
0.300036
52
0.30004
37
0.300043
40
0.300046
41
0.30005
34
0.300053
38
0.300057
44
0.30006
39
0.300063
37
0.300067
43
0.30007
42
0.300073
34
0.300077
54
0.30008
40
0.300083
30
0.300087
38
0.30009
49
0.300094
41
0.300097
53
0.3001
30
0.300104
35
0.300107
33
0.30011
45
0.300114
40
0.300117
41
0.300121
31
0.300124
36
0.300127
28
0.300131
37
0.300134
40
0.300137
37
0.300141
35
0.300144
36
0.300147
54
0.300151
36
0.300154
29
0.300158
36
0.300161
43
0.300164
39
0.300168
33
0.300171
46
0.300174
43
0.300178
41
0.300181
41
0.300184
32
0.300188
34
0.300191
36
0.300195
36
0.300198
47
0.300201
44
0.300205
48
0.300208
38
0.300211
49
0.300215
46
0.300218
39
0.300222
31
0.300225
44
0.300228
33
0.300232
40
0.300235
28
0.300238
47
0.300242
49
0.300245
37
0.300248
37
0.300252
36
0.300255
39
0.300259
42
0.300262
50
0.300265
37
0.300269
38
0.300272
42
0.300275
40
0.300279
41
0.300282
38
0.300285
38
0.300289
46
0.300292
30
0.300296
41
0.300299
35
0.300302
33
0.300306
41
0.300309
39
0.300312
36
0.300316
35
0.300319
51
0.300323
53
0.300326
44
0.300329
43
0.300333
39
0.300336
42
0.300339
40
0.300343
40
0.300346
42
0.300349
39
0.300353
40
0.300356
49
0.30036
37
0.300363
40
0.300366
41
0.30037
36
0.300373
38
0.300376
48
0.30038
50
0.300383
45
0.30039
38
0.300401
35
0.300412
42
0.300423
29
0.300434
34
0.300445
38
0.300456
38
0.300467
37
0.300478
50
0.300489
32
0.3005
35
0.300511
39
0.300522
Au 4f/10
Not Specified
2005
9
14
13
43
50
0
4
   Lens Mode:Hybrid   Resolution:Pass energy 10    Iris(Aperture):slot(Slot)
   Anode:Mono(Al (Mono))(150 W)   Step(meV): 100.0    Dwell(ms): 200        Sweeps: 16       Acquisition Time(s): 963
   Acquired On :05/09/14 13:43:50   C/N :On

XPS
16384
16384
0
Mono(Al (Mono))
1486.69
150
1E+37
1E+37
6000
6000
1E+37
1E+37
FAT
10
1E+37
-4.455
0
1E+37
1E+37
1E+37
1E+37
Au
4f
-1
Kinetic Energy
eV
1386.69
0.1
2
Intensity
d
Transmission
d
pulse counting
0.2
16
0
1E+37
1E+37
1E+37
0
602
7
38
0.306691
0.309997
21
0.306691
20
0.306702
22
0.306713
18
0.306725
24
0.306736
28
0.306747
21
0.306758
23
0.306769
21
0.30678
26
0.306791
19
0.306802
16
0.306813
24
0.306824
26
0.306835
23
0.306846
21
0.306857
25
0.306868
25
0.306879
26
0.30689
24
0.306901
20
0.306912
20
0.306923
22
0.306934
14
0.306945
29
0.306956
29
0.306967
25
0.306978
22
0.306989
24
0.307
23
0.307011
20
0.307022
24
0.307033
31
0.307044
23
0.307055
21
0.307066
21
0.307077
31
0.307088
29
0.307099
16
0.30711
24
0.307121
22
0.307132
23
0.307143
21
0.307154
18
0.307165
26
0.307176
26
0.307187
17
0.307198
26
0.307209
21
0.30722
18
0.307231
25
0.307242
22
0.307253
28
0.307264
21
0.307275
20
0.307286
20
0.307297
18
0.307308
23
0.307319
23
0.30733
20
0.307341
24
0.307353
19
0.307364
24
0.307375
25
0.307386
26
0.307397
15
0.307408
23
0.307419
25
0.30743
21
0.307441
16
0.307452
19
0.307463
19
0.307474
20
0.307485
22
0.307496
22
0.307507
26
0.307518
22
0.307529
24
0.30754
20
0.307551
23
0.307562
19
0.307573
20
0.307584
19
0.307595
31
0.307606
19
0.307617
18
0.307628
22
0.307639
30
0.30765
21
0.307661
18
0.307672
19
0.307683
26
0.307694
28
0.307705
25
0.307716
19
0.307727
31
0.307738
23
0.307749
22
0.30776
20
0.307771
22
0.307782
20
0.307793
18
0.307804
18
0.307815
21
0.307826
25
0.307837
17
0.307848
19
0.307859
17
0.30787
24
0.307881
15
0.307892
18
0.307903
19
0.307914
19
0.307925
12
0.307936
26
0.307947
17
0.307958
20
0.307969
13
0.307981
22
0.307992
21
0.308003
20
0.308014
22
0.308025
16
0.308036
15
0.308047
29
0.308058
27
0.308069
26
0.30808
19
0.308091
30
0.308102
24
0.308113
24
0.308124
32
0.308135
21
0.308146
31
0.308157
18
0.308168
21
0.308179
28
0.30819
20
0.308201
26
0.308212
22
0.308223
18
0.308234
14
0.308245
18
0.308256
21
0.308267
26
0.308278
22
0.308289
16
0.3083
27
0.308311
29
0.308322
27
0.308333
15
0.308344
24
0.308355
17
0.308366
21
0.308377
18
0.308388
22
0.308399
27
0.30841
28
0.308421
32
0.308432
24
0.308443
29
0.308454
15
0.308465
24
0.308476
25
0.308487
28
0.308498
28
0.308509
18
0.30852
24
0.308531
30
0.308542
16
0.308553
20
0.308564
21
0.308575
30
0.308586
30
0.308597
31
0.308608
38
0.308619
20
0.308631
19
0.308642
32
0.308653
23
0.308664
21
0.308675
21
0.308686
19
0.308697
31
0.308708
20
0.308719
19
0.30873
18
0.308741
18
0.308752
19
0.308763
21
0.308774
24
0.308785
13
0.308796
18
0.308807
16
0.308818
17
0.308829
17
0.30884
21
0.308851
17
0.308862
22
0.308873
16
0.308884
19
0.308895
21
0.308906
18
0.308917
13
0.308928
21
0.308939
17
0.30895
20
0.308961
17
0.308972
20
0.308983
11
0.308994
17
0.309005
15
0.309016
15
0.309027
18
0.309038
21
0.309049
18
0.30906
18
0.309071
20
0.309082
18
0.309093
18
0.309104
18
0.309115
15
0.309126
14
0.309137
15
0.309148
10
0.309159
24
0.30917
22
0.309181
18
0.309192
20
0.309203
15
0.309214
18
0.309225
21
0.309236
18
0.309247
18
0.309259
17
0.30927
24
0.309281
21
0.309292
11
0.309303
16
0.309314
22
0.309325
17
0.309336
20
0.309347
13
0.309358
21
0.309369
23
0.30938
13
0.309391
20
0.309402
16
0.309413
23
0.309424
19
0.309435
22
0.309446
24
0.309457
16
0.309468
22
0.309479
20
0.30949
13
0.309501
14
0.309512
16
0.309523
25
0.309534
30
0.309545
16
0.309556
14
0.309567
15
0.309578
27
0.309589
28
0.3096
23
0.309611
22
0.309622
15
0.309633
19
0.309644
15
0.309655
17
0.309666
14
0.309677
19
0.309688
20
0.309699
20
0.30971
24
0.309721
14
0.309732
16
0.309743
20
0.309754
7
0.309765
12
0.309776
17
0.309787
19
0.309798
19
0.309809
22
0.30982
13
0.309831
19
0.309842
10
0.309853
15
0.309864
16
0.309875
19
0.309886
15
0.309898
17
0.309909
12
0.30992
21
0.309931
10
0.309942
18
0.309953
16
0.309964
17
0.309975
18
0.309986
21
0.309997
S 2p/13
Not Specified
2005
9
14
17
23
21
0
4
   Lens Mode:Hybrid   Resolution:Pass energy 10    Iris(Aperture):slot(Slot)
   Anode:Mono(Al (Mono))(150 W)   Step(meV): 100.0    Dwell(ms): 333        Sweeps: 250      Acquisition Time(s): 15083
   Acquired On :05/09/14 17:23:21   C/N :On

XPS
16384
16384
0
Mono(Al (Mono))
1486.69
150
1E+37
1E+37
6000
6000
1E+37
1E+37
FAT
10
1E+37
-4.455
0
1E+37
1E+37
1E+37
1E+37
S
2p
-1
Kinetic Energy
eV
1312.69
0.1
2
Intensity
d
Transmission
d
pulse counting
0.333333
250
0
1E+37
1E+37
1E+37
0
362
554
699
0.299821
0.300522
644
0.299821
636
0.299824
650
0.299828
650
0.299831
610
0.299834
598
0.299838
591
0.299841
600
0.299844
640
0.299848
611
0.299851
625
0.299855
616
0.299858
607
0.299861
626
0.299865
611
0.299868
617
0.299871
628
0.299875
605
0.299878
644
0.299882
621
0.299885
631
0.299888
579
0.299892
691
0.299895
589
0.299898
617
0.299902
607
0.299905
636
0.299908
605
0.299912
616
0.299915
597
0.299919
590
0.299922
580
0.299925
555
0.299929
554
0.299932
599
0.299935
609
0.299939
559
0.299942
620
0.299945
644
0.299949
583
0.299952
645
0.299956
654
0.299959
636
0.299962
665
0.299966
633
0.299969
605
0.299972
614
0.299976
631
0.299979
690
0.299983
642
0.299986
647
0.299989
613
0.299993
645
0.299996
652
0.299999
647
0.300003
623
0.300006
641
0.300009
699
0.300013
659
0.300016
635
0.30002
633
0.300023
640
0.300026
618
0.30003
660
0.300033
635
0.300036
676
0.30004
677
0.300043
646
0.300046
646
0.30005
618
0.300053
652
0.300057
627
0.30006
634
0.300063
628
0.300067
649
0.30007
644
0.300073
644
0.300077
657
0.30008
630
0.300083
652
0.300087
619
0.30009
641
0.300094
595
0.300097
595
0.3001
685
0.300104
563
0.300107
657
0.30011
610
0.300114
642
0.300117
646
0.300121
652
0.300124
639
0.300127
618
0.300131
598
0.300134
641
0.300137
623
0.300141
630
0.300144
653
0.300147
667
0.300151
631
0.300154
669
0.300158
654
0.300161
605
0.300164
629
0.300168
639
0.300171
685
0.300174
629
0.300178
617
0.300181
593
0.300184
642
0.300188
626
0.300191
634
0.300195
598
0.300198
626
0.300201
592
0.300205
612
0.300208
591
0.300211
641
0.300215
610
0.300218
642
0.300222
634
0.300225
633
0.300228
656
0.300232
664
0.300235
604
0.300238
626
0.300242
647
0.300245
598
0.300248
642
0.300252
672
0.300255
609
0.300259
630
0.300262
642
0.300265
638
0.300269
598
0.300272
607
0.300275
620
0.300279
614
0.300282
609
0.300285
574
0.300289
637
0.300292
625
0.300296
602
0.300299
599
0.300302
666
0.300306
638
0.300309
601
0.300312
561
0.300316
628
0.300319
602
0.300323
631
0.300326
640
0.300329
622
0.300333
608
0.300336
645
0.300339
622
0.300343
661
0.300346
596
0.300349
641
0.300353
629
0.300356
635
0.30036
659
0.300363
606
0.300366
573
0.30037
569
0.300373
614
0.300376
613
0.30038
586
0.300383
633
0.30039
643
0.300401
644
0.300412
602
0.300423
637
0.300434
628
0.300445
629
0.300456
609
0.300467
660
0.300478
623
0.300489
673
0.3005
632
0.300511
589
0.300522
Au 4f/14
Not Specified
2005
9
14
17
23
21
0
4
   Lens Mode:Hybrid   Resolution:Pass energy 10    Iris(Aperture):slot(Slot)
   Anode:Mono(Al (Mono))(150 W)   Step(meV): 100.0    Dwell(ms): 200        Sweeps: 250      Acquisition Time(s): 15050
   Acquired On :05/09/14 17:23:21   C/N :On

XPS
16384
16384
0
Mono(Al (Mono))
1486.69
150
1E+37
1E+37
6000
6000
1E+37
1E+37
FAT
10
1E+37
-4.455
0
1E+37
1E+37
1E+37
1E+37
Au
4f
-1
Kinetic Energy
eV
1386.69
0.1
2
Intensity
d
Transmission
d
pulse counting
0.2
250
0
1E+37
1E+37
1E+37
0
602
259
413
0.306691
0.309997
371
0.306691
383
0.306702
360
0.306713
362
0.306725
368
0.306736
403
0.306747
387
0.306758
367
0.306769
366
0.30678
363
0.306791
387
0.306802
369
0.306813
374
0.306824
327
0.306835
339
0.306846
323
0.306857
335
0.306868
362
0.306879
340
0.30689
344
0.306901
358
0.306912
370
0.306923
369
0.306934
339
0.306945
363
0.306956
322
0.306967
391
0.306978
377
0.306989
352
0.307
309
0.307011
338
0.307022
356
0.307033
339
0.307044
339
0.307055
359
0.307066
370
0.307077
353
0.307088
347
0.307099
394
0.30711
366
0.307121
346
0.307132
352
0.307143
372
0.307154
369
0.307165
373
0.307176
350
0.307187
347
0.307198
359
0.307209
360
0.30722
361
0.307231
341
0.307242
376
0.307253
346
0.307264
351
0.307275
343
0.307286
353
0.307297
356
0.307308
348
0.307319
329
0.30733
334
0.307341
341
0.307353
389
0.307364
350
0.307375
367
0.307386
382
0.307397
375
0.307408
366
0.307419
369
0.30743
373
0.307441
367
0.307452
321
0.307463
367
0.307474
356
0.307485
365
0.307496
379
0.307507
369
0.307518
388
0.307529
376
0.30754
363
0.307551
342
0.307562
366
0.307573
343
0.307584
343
0.307595
378
0.307606
344
0.307617
349
0.307628
368
0.307639
341
0.30765
330
0.307661
360
0.307672
368
0.307683
328
0.307694
357
0.307705
329
0.307716
342
0.307727
347
0.307738
327
0.307749
355
0.30776
354
0.307771
300
0.307782
335
0.307793
319
0.307804
329
0.307815
322
0.307826
348
0.307837
333
0.307848
323
0.307859
318
0.30787
334
0.307881
336
0.307892
333
0.307903
355
0.307914
324
0.307925
330
0.307936
342
0.307947
321
0.307958
363
0.307969
321
0.307981
336
0.307992
362
0.308003
340
0.308014
351
0.308025
356
0.308036
366
0.308047
331
0.308058
366
0.308069
375
0.30808
388
0.308091
383
0.308102
385
0.308113
374
0.308124
371
0.308135
378
0.308146
363
0.308157
370
0.308168
398
0.308179
382
0.30819
380
0.308201
381
0.308212
404
0.308223
413
0.308234
390
0.308245
371
0.308256
346
0.308267
347
0.308278
338
0.308289
361
0.3083
336
0.308311
329
0.308322
339
0.308333
313
0.308344
359
0.308355
352
0.308366
351
0.308377
350
0.308388
357
0.308399
348
0.30841
336
0.308421
350
0.308432
336
0.308443
390
0.308454
374
0.308465
341
0.308476
390
0.308487
372
0.308498
397
0.308509
376
0.30852
409
0.308531
395
0.308542
395
0.308553
407
0.308564
392
0.308575
372
0.308586
405
0.308597
324
0.308608
400
0.308619
385
0.308631
377
0.308642
371
0.308653
376
0.308664
352
0.308675
370
0.308686
366
0.308697
376
0.308708
364
0.308719
372
0.30873
351
0.308741
345
0.308752
323
0.308763
317
0.308774
352
0.308785
320
0.308796
337
0.308807
340
0.308818
312
0.308829
286
0.30884
298
0.308851
290
0.308862
286
0.308873
300
0.308884
306
0.308895
288
0.308906
309
0.308917
299
0.308928
296
0.308939
303
0.30895
284
0.308961
315
0.308972
337
0.308983
309
0.308994
279
0.309005
333
0.309016
327
0.309027
313
0.309038
340
0.309049
300
0.30906
302
0.309071
300
0.309082
331
0.309093
320
0.309104
283
0.309115
316
0.309126
312
0.309137
331
0.309148
272
0.309159
313
0.30917
324
0.309181
273
0.309192
262
0.309203
287
0.309214
315
0.309225
279
0.309236
293
0.309247
299
0.309259
306
0.30927
317
0.309281
347
0.309292
285
0.309303
299
0.309314
286
0.309325
303
0.309336
288
0.309347
315
0.309358
321
0.309369
302
0.30938
292
0.309391
295
0.309402
314
0.309413
286
0.309424
306
0.309435
314
0.309446
292
0.309457
298
0.309468
302
0.309479
304
0.30949
288
0.309501
280
0.309512
281
0.309523
314
0.309534
310
0.309545
313
0.309556
301
0.309567
315
0.309578
309
0.309589
306
0.3096
291
0.309611
280
0.309622
270
0.309633
304
0.309644
292
0.309655
302
0.309666
262
0.309677
280
0.309688
282
0.309699
286
0.30971
277
0.309721
278
0.309732
265
0.309743
260
0.309754
269
0.309765
309
0.309776
284
0.309787
284
0.309798
298
0.309809
277
0.30982
320
0.309831
269
0.309842
300
0.309853
278
0.309864
291
0.309875
283
0.309886
305
0.309898
306
0.309909
274
0.30992
261
0.309931
268
0.309942
299
0.309953
304
0.309964
283
0.309975
259
0.309986
278
0.309997
end of experiment